2020-05-29 14:10:28.654 | ERROR    | proxypool.processors.getter:run:36 - An error has been caught in function 'run', process 'Process-2' (25504), thread 'MainThread' (27640):
Traceback (most recent call last):
  File "<string>", line 1, in <module>
  File "D:\python37\lib\multiprocessing\spawn.py", line 105, in spawn_main
    exitcode = _main(fd)
               │     └ 3
               └ <function _main at 0x00000158F1133EA0>
  File "D:\python37\lib\multiprocessing\spawn.py", line 118, in _main
    return self._bootstrap()
           │    └ <function BaseProcess._bootstrap at 0x00000158F10F78C8>
           └ <Process(Process-2, started)>
  File "D:\python37\lib\multiprocessing\process.py", line 297, in _bootstrap
    self.run()
    │    └ <function BaseProcess.run at 0x00000158F10E8F28>
    └ <Process(Process-2, started)>
  File "D:\python37\lib\multiprocessing\process.py", line 99, in run
    self._target(*self._args, **self._kwargs)
    │    │        │    │        │    └ {}
    │    │        │    │        └ <Process(Process-2, started)>
    │    │        │    └ ()
    │    │        └ <Process(Process-2, started)>
    │    └ <bound method Scheduler.run_getter of <proxypool.scheduler.Scheduler object at 0x00000158F2A7CB38>>
    └ <Process(Process-2, started)>

  File "E:\代理池\ProxyPool\proxypool\scheduler.py", line 48, in run_getter
    getter.run()
    │      └ <function Getter.run at 0x00000158F2643D08>
    └ <proxypool.processors.getter.Getter object at 0x00000158F10F1D30>

> File "E:\代理池\ProxyPool\proxypool\processors\getter.py", line 36, in run
    for proxy in crawler.crawl():
        │        │       └ <function BaseCrawler.crawl at 0x00000158F2643510>
        │        └ <public.kuaidaili.KuaidailiCrawler object at 0x00000158F2A7CD30>
        └ Proxy(host='1.197.204.242', port='9999')

  File "E:\代理池\ProxyPool\proxypool\crawlers\base.py", line 25, in crawl
    html = self.fetch(url)
    │      │    │     └ 'https://www.kuaidaili.com/free/inha/2/'
    │      │    └ <function BaseCrawler.fetch at 0x00000158F2643488>
    │      └ <public.kuaidaili.KuaidailiCrawler object at 0x00000158F2A7CD30>
    └ '<!DOCTYPE html>\n<html>\n<head>\n<meta http-equiv="X-UA-Compatible" content="IE=edge" />\n<meta http-equiv="Content-Type" co...

  File "D:\python37\lib\site-packages\retrying.py", line 49, in wrapped_f
    return Retrying(*dargs, **dkw).call(f, *args, **kw)
           │         │        │         │   │       └ {}
           │         │        │         │   └ (<public.kuaidaili.KuaidailiCrawler object at 0x00000158F2A7CD30>, 'https://www.kuaidaili.com/free/inha/2/')
           │         │        │         └ <function BaseCrawler.fetch at 0x00000158F2643400>
           │         │        └ {'stop_max_attempt_number': 3, 'retry_on_result': <function BaseCrawler.<lambda> at 0x00000158F22847B8>}
           │         └ ()
           └ <class 'retrying.Retrying'>
  File "D:\python37\lib\site-packages\retrying.py", line 214, in call
    raise RetryError(attempt)
          │          └ Attempts: 3, Value: None
          └ <class 'retrying.RetryError'>

retrying.RetryError: RetryError[Attempts: 3, Value: None]
2020-05-29 14:12:14.004 | ERROR    | proxypool.processors.getter:run:36 - An error has been caught in function 'run', process 'Process-2' (25504), thread 'MainThread' (27640):
Traceback (most recent call last):
  File "<string>", line 1, in <module>
  File "D:\python37\lib\multiprocessing\spawn.py", line 105, in spawn_main
    exitcode = _main(fd)
               │     └ 3
               └ <function _main at 0x00000158F1133EA0>
  File "D:\python37\lib\multiprocessing\spawn.py", line 118, in _main
    return self._bootstrap()
           │    └ <function BaseProcess._bootstrap at 0x00000158F10F78C8>
           └ <Process(Process-2, started)>
  File "D:\python37\lib\multiprocessing\process.py", line 297, in _bootstrap
    self.run()
    │    └ <function BaseProcess.run at 0x00000158F10E8F28>
    └ <Process(Process-2, started)>
  File "D:\python37\lib\multiprocessing\process.py", line 99, in run
    self._target(*self._args, **self._kwargs)
    │    │        │    │        │    └ {}
    │    │        │    │        └ <Process(Process-2, started)>
    │    │        │    └ ()
    │    │        └ <Process(Process-2, started)>
    │    └ <bound method Scheduler.run_getter of <proxypool.scheduler.Scheduler object at 0x00000158F2A7CB38>>
    └ <Process(Process-2, started)>

  File "E:\代理池\ProxyPool\proxypool\scheduler.py", line 48, in run_getter
    getter.run()
    │      └ <function Getter.run at 0x00000158F2643D08>
    └ <proxypool.processors.getter.Getter object at 0x00000158F10F1D30>

> File "E:\代理池\ProxyPool\proxypool\processors\getter.py", line 36, in run
    for proxy in crawler.crawl():
        │        │       └ <function BaseCrawler.crawl at 0x00000158F2643510>
        │        └ <public.kuaidaili.KuaidailiCrawler object at 0x00000158F2A7CD30>
        └ Proxy(host='1.197.204.242', port='9999')

  File "E:\代理池\ProxyPool\proxypool\crawlers\base.py", line 25, in crawl
    html = self.fetch(url)
    │      │    │     └ 'https://www.kuaidaili.com/free/inha/2/'
    │      │    └ <function BaseCrawler.fetch at 0x00000158F2643488>
    │      └ <public.kuaidaili.KuaidailiCrawler object at 0x00000158F2A7CD30>
    └ '<!DOCTYPE html>\n<html>\n<head>\n<meta http-equiv="X-UA-Compatible" content="IE=edge" />\n<meta http-equiv="Content-Type" co...

  File "D:\python37\lib\site-packages\retrying.py", line 49, in wrapped_f
    return Retrying(*dargs, **dkw).call(f, *args, **kw)
           │         │        │         │   │       └ {}
           │         │        │         │   └ (<public.kuaidaili.KuaidailiCrawler object at 0x00000158F2A7CD30>, 'https://www.kuaidaili.com/free/inha/2/')
           │         │        │         └ <function BaseCrawler.fetch at 0x00000158F2643400>
           │         │        └ {'stop_max_attempt_number': 3, 'retry_on_result': <function BaseCrawler.<lambda> at 0x00000158F22847B8>}
           │         └ ()
           └ <class 'retrying.Retrying'>
  File "D:\python37\lib\site-packages\retrying.py", line 214, in call
    raise RetryError(attempt)
          │          └ Attempts: 3, Value: None
          └ <class 'retrying.RetryError'>

retrying.RetryError: RetryError[Attempts: 3, Value: None]
2020-05-29 14:14:02.043 | ERROR    | proxypool.processors.getter:run:36 - An error has been caught in function 'run', process 'Process-2' (25504), thread 'MainThread' (27640):
Traceback (most recent call last):
  File "<string>", line 1, in <module>
  File "D:\python37\lib\multiprocessing\spawn.py", line 105, in spawn_main
    exitcode = _main(fd)
               │     └ 3
               └ <function _main at 0x00000158F1133EA0>
  File "D:\python37\lib\multiprocessing\spawn.py", line 118, in _main
    return self._bootstrap()
           │    └ <function BaseProcess._bootstrap at 0x00000158F10F78C8>
           └ <Process(Process-2, started)>
  File "D:\python37\lib\multiprocessing\process.py", line 297, in _bootstrap
    self.run()
    │    └ <function BaseProcess.run at 0x00000158F10E8F28>
    └ <Process(Process-2, started)>
  File "D:\python37\lib\multiprocessing\process.py", line 99, in run
    self._target(*self._args, **self._kwargs)
    │    │        │    │        │    └ {}
    │    │        │    │        └ <Process(Process-2, started)>
    │    │        │    └ ()
    │    │        └ <Process(Process-2, started)>
    │    └ <bound method Scheduler.run_getter of <proxypool.scheduler.Scheduler object at 0x00000158F2A7CB38>>
    └ <Process(Process-2, started)>

  File "E:\代理池\ProxyPool\proxypool\scheduler.py", line 48, in run_getter
    getter.run()
    │      └ <function Getter.run at 0x00000158F2643D08>
    └ <proxypool.processors.getter.Getter object at 0x00000158F10F1D30>

> File "E:\代理池\ProxyPool\proxypool\processors\getter.py", line 36, in run
    for proxy in crawler.crawl():
        │        │       └ <function BaseCrawler.crawl at 0x00000158F2643510>
        │        └ <public.kuaidaili.KuaidailiCrawler object at 0x00000158F2A7CD30>
        └ Proxy(host='1.197.204.242', port='9999')

  File "E:\代理池\ProxyPool\proxypool\crawlers\base.py", line 25, in crawl
    html = self.fetch(url)
    │      │    │     └ 'https://www.kuaidaili.com/free/inha/2/'
    │      │    └ <function BaseCrawler.fetch at 0x00000158F2643488>
    │      └ <public.kuaidaili.KuaidailiCrawler object at 0x00000158F2A7CD30>
    └ '<!DOCTYPE html>\n<html>\n<head>\n<meta http-equiv="X-UA-Compatible" content="IE=edge" />\n<meta http-equiv="Content-Type" co...

  File "D:\python37\lib\site-packages\retrying.py", line 49, in wrapped_f
    return Retrying(*dargs, **dkw).call(f, *args, **kw)
           │         │        │         │   │       └ {}
           │         │        │         │   └ (<public.kuaidaili.KuaidailiCrawler object at 0x00000158F2A7CD30>, 'https://www.kuaidaili.com/free/inha/2/')
           │         │        │         └ <function BaseCrawler.fetch at 0x00000158F2643400>
           │         │        └ {'stop_max_attempt_number': 3, 'retry_on_result': <function BaseCrawler.<lambda> at 0x00000158F22847B8>}
           │         └ ()
           └ <class 'retrying.Retrying'>
  File "D:\python37\lib\site-packages\retrying.py", line 214, in call
    raise RetryError(attempt)
          │          └ Attempts: 3, Value: None
          └ <class 'retrying.RetryError'>

retrying.RetryError: RetryError[Attempts: 3, Value: None]
2020-05-29 14:15:47.522 | ERROR    | proxypool.processors.getter:run:36 - An error has been caught in function 'run', process 'Process-2' (25504), thread 'MainThread' (27640):
Traceback (most recent call last):
  File "<string>", line 1, in <module>
  File "D:\python37\lib\multiprocessing\spawn.py", line 105, in spawn_main
    exitcode = _main(fd)
               │     └ 3
               └ <function _main at 0x00000158F1133EA0>
  File "D:\python37\lib\multiprocessing\spawn.py", line 118, in _main
    return self._bootstrap()
           │    └ <function BaseProcess._bootstrap at 0x00000158F10F78C8>
           └ <Process(Process-2, started)>
  File "D:\python37\lib\multiprocessing\process.py", line 297, in _bootstrap
    self.run()
    │    └ <function BaseProcess.run at 0x00000158F10E8F28>
    └ <Process(Process-2, started)>
  File "D:\python37\lib\multiprocessing\process.py", line 99, in run
    self._target(*self._args, **self._kwargs)
    │    │        │    │        │    └ {}
    │    │        │    │        └ <Process(Process-2, started)>
    │    │        │    └ ()
    │    │        └ <Process(Process-2, started)>
    │    └ <bound method Scheduler.run_getter of <proxypool.scheduler.Scheduler object at 0x00000158F2A7CB38>>
    └ <Process(Process-2, started)>

  File "E:\代理池\ProxyPool\proxypool\scheduler.py", line 48, in run_getter
    getter.run()
    │      └ <function Getter.run at 0x00000158F2643D08>
    └ <proxypool.processors.getter.Getter object at 0x00000158F10F1D30>

> File "E:\代理池\ProxyPool\proxypool\processors\getter.py", line 36, in run
    for proxy in crawler.crawl():
        │        │       └ <function BaseCrawler.crawl at 0x00000158F2643510>
        │        └ <public.kuaidaili.KuaidailiCrawler object at 0x00000158F2A7CD30>
        └ Proxy(host='1.197.204.242', port='9999')

  File "E:\代理池\ProxyPool\proxypool\crawlers\base.py", line 25, in crawl
    html = self.fetch(url)
    │      │    │     └ 'https://www.kuaidaili.com/free/inha/2/'
    │      │    └ <function BaseCrawler.fetch at 0x00000158F2643488>
    │      └ <public.kuaidaili.KuaidailiCrawler object at 0x00000158F2A7CD30>
    └ '<!DOCTYPE html>\n<html>\n<head>\n<meta http-equiv="X-UA-Compatible" content="IE=edge" />\n<meta http-equiv="Content-Type" co...

  File "D:\python37\lib\site-packages\retrying.py", line 49, in wrapped_f
    return Retrying(*dargs, **dkw).call(f, *args, **kw)
           │         │        │         │   │       └ {}
           │         │        │         │   └ (<public.kuaidaili.KuaidailiCrawler object at 0x00000158F2A7CD30>, 'https://www.kuaidaili.com/free/inha/2/')
           │         │        │         └ <function BaseCrawler.fetch at 0x00000158F2643400>
           │         │        └ {'stop_max_attempt_number': 3, 'retry_on_result': <function BaseCrawler.<lambda> at 0x00000158F22847B8>}
           │         └ ()
           └ <class 'retrying.Retrying'>
  File "D:\python37\lib\site-packages\retrying.py", line 214, in call
    raise RetryError(attempt)
          │          └ Attempts: 3, Value: None
          └ <class 'retrying.RetryError'>

retrying.RetryError: RetryError[Attempts: 3, Value: None]
2020-05-29 14:17:32.573 | ERROR    | proxypool.processors.getter:run:36 - An error has been caught in function 'run', process 'Process-2' (25504), thread 'MainThread' (27640):
Traceback (most recent call last):
  File "<string>", line 1, in <module>
  File "D:\python37\lib\multiprocessing\spawn.py", line 105, in spawn_main
    exitcode = _main(fd)
               │     └ 3
               └ <function _main at 0x00000158F1133EA0>
  File "D:\python37\lib\multiprocessing\spawn.py", line 118, in _main
    return self._bootstrap()
           │    └ <function BaseProcess._bootstrap at 0x00000158F10F78C8>
           └ <Process(Process-2, started)>
  File "D:\python37\lib\multiprocessing\process.py", line 297, in _bootstrap
    self.run()
    │    └ <function BaseProcess.run at 0x00000158F10E8F28>
    └ <Process(Process-2, started)>
  File "D:\python37\lib\multiprocessing\process.py", line 99, in run
    self._target(*self._args, **self._kwargs)
    │    │        │    │        │    └ {}
    │    │        │    │        └ <Process(Process-2, started)>
    │    │        │    └ ()
    │    │        └ <Process(Process-2, started)>
    │    └ <bound method Scheduler.run_getter of <proxypool.scheduler.Scheduler object at 0x00000158F2A7CB38>>
    └ <Process(Process-2, started)>

  File "E:\代理池\ProxyPool\proxypool\scheduler.py", line 48, in run_getter
    getter.run()
    │      └ <function Getter.run at 0x00000158F2643D08>
    └ <proxypool.processors.getter.Getter object at 0x00000158F10F1D30>

> File "E:\代理池\ProxyPool\proxypool\processors\getter.py", line 36, in run
    for proxy in crawler.crawl():
        │        │       └ <function BaseCrawler.crawl at 0x00000158F2643510>
        │        └ <public.kuaidaili.KuaidailiCrawler object at 0x00000158F2A7CD30>
        └ Proxy(host='1.197.204.242', port='9999')

  File "E:\代理池\ProxyPool\proxypool\crawlers\base.py", line 25, in crawl
    html = self.fetch(url)
    │      │    │     └ 'https://www.kuaidaili.com/free/inha/2/'
    │      │    └ <function BaseCrawler.fetch at 0x00000158F2643488>
    │      └ <public.kuaidaili.KuaidailiCrawler object at 0x00000158F2A7CD30>
    └ '<!DOCTYPE html>\n<html>\n<head>\n<meta http-equiv="X-UA-Compatible" content="IE=edge" />\n<meta http-equiv="Content-Type" co...

  File "D:\python37\lib\site-packages\retrying.py", line 49, in wrapped_f
    return Retrying(*dargs, **dkw).call(f, *args, **kw)
           │         │        │         │   │       └ {}
           │         │        │         │   └ (<public.kuaidaili.KuaidailiCrawler object at 0x00000158F2A7CD30>, 'https://www.kuaidaili.com/free/inha/2/')
           │         │        │         └ <function BaseCrawler.fetch at 0x00000158F2643400>
           │         │        └ {'stop_max_attempt_number': 3, 'retry_on_result': <function BaseCrawler.<lambda> at 0x00000158F22847B8>}
           │         └ ()
           └ <class 'retrying.Retrying'>
  File "D:\python37\lib\site-packages\retrying.py", line 214, in call
    raise RetryError(attempt)
          │          └ Attempts: 3, Value: None
          └ <class 'retrying.RetryError'>

retrying.RetryError: RetryError[Attempts: 3, Value: None]
2020-05-29 14:19:17.934 | ERROR    | proxypool.processors.getter:run:36 - An error has been caught in function 'run', process 'Process-2' (25504), thread 'MainThread' (27640):
Traceback (most recent call last):
  File "<string>", line 1, in <module>
  File "D:\python37\lib\multiprocessing\spawn.py", line 105, in spawn_main
    exitcode = _main(fd)
               │     └ 3
               └ <function _main at 0x00000158F1133EA0>
  File "D:\python37\lib\multiprocessing\spawn.py", line 118, in _main
    return self._bootstrap()
           │    └ <function BaseProcess._bootstrap at 0x00000158F10F78C8>
           └ <Process(Process-2, started)>
  File "D:\python37\lib\multiprocessing\process.py", line 297, in _bootstrap
    self.run()
    │    └ <function BaseProcess.run at 0x00000158F10E8F28>
    └ <Process(Process-2, started)>
  File "D:\python37\lib\multiprocessing\process.py", line 99, in run
    self._target(*self._args, **self._kwargs)
    │    │        │    │        │    └ {}
    │    │        │    │        └ <Process(Process-2, started)>
    │    │        │    └ ()
    │    │        └ <Process(Process-2, started)>
    │    └ <bound method Scheduler.run_getter of <proxypool.scheduler.Scheduler object at 0x00000158F2A7CB38>>
    └ <Process(Process-2, started)>

  File "E:\代理池\ProxyPool\proxypool\scheduler.py", line 48, in run_getter
    getter.run()
    │      └ <function Getter.run at 0x00000158F2643D08>
    └ <proxypool.processors.getter.Getter object at 0x00000158F10F1D30>

> File "E:\代理池\ProxyPool\proxypool\processors\getter.py", line 36, in run
    for proxy in crawler.crawl():
        │        │       └ <function BaseCrawler.crawl at 0x00000158F2643510>
        │        └ <public.kuaidaili.KuaidailiCrawler object at 0x00000158F2A7CD30>
        └ Proxy(host='1.197.204.242', port='9999')

  File "E:\代理池\ProxyPool\proxypool\crawlers\base.py", line 25, in crawl
    html = self.fetch(url)
    │      │    │     └ 'https://www.kuaidaili.com/free/inha/2/'
    │      │    └ <function BaseCrawler.fetch at 0x00000158F2643488>
    │      └ <public.kuaidaili.KuaidailiCrawler object at 0x00000158F2A7CD30>
    └ '<!DOCTYPE html>\n<html>\n<head>\n<meta http-equiv="X-UA-Compatible" content="IE=edge" />\n<meta http-equiv="Content-Type" co...

  File "D:\python37\lib\site-packages\retrying.py", line 49, in wrapped_f
    return Retrying(*dargs, **dkw).call(f, *args, **kw)
           │         │        │         │   │       └ {}
           │         │        │         │   └ (<public.kuaidaili.KuaidailiCrawler object at 0x00000158F2A7CD30>, 'https://www.kuaidaili.com/free/inha/2/')
           │         │        │         └ <function BaseCrawler.fetch at 0x00000158F2643400>
           │         │        └ {'stop_max_attempt_number': 3, 'retry_on_result': <function BaseCrawler.<lambda> at 0x00000158F22847B8>}
           │         └ ()
           └ <class 'retrying.Retrying'>
  File "D:\python37\lib\site-packages\retrying.py", line 214, in call
    raise RetryError(attempt)
          │          └ Attempts: 3, Value: None
          └ <class 'retrying.RetryError'>

retrying.RetryError: RetryError[Attempts: 3, Value: None]
2020-05-29 14:21:03.121 | ERROR    | proxypool.processors.getter:run:36 - An error has been caught in function 'run', process 'Process-2' (25504), thread 'MainThread' (27640):
Traceback (most recent call last):
  File "<string>", line 1, in <module>
  File "D:\python37\lib\multiprocessing\spawn.py", line 105, in spawn_main
    exitcode = _main(fd)
               │     └ 3
               └ <function _main at 0x00000158F1133EA0>
  File "D:\python37\lib\multiprocessing\spawn.py", line 118, in _main
    return self._bootstrap()
           │    └ <function BaseProcess._bootstrap at 0x00000158F10F78C8>
           └ <Process(Process-2, started)>
  File "D:\python37\lib\multiprocessing\process.py", line 297, in _bootstrap
    self.run()
    │    └ <function BaseProcess.run at 0x00000158F10E8F28>
    └ <Process(Process-2, started)>
  File "D:\python37\lib\multiprocessing\process.py", line 99, in run
    self._target(*self._args, **self._kwargs)
    │    │        │    │        │    └ {}
    │    │        │    │        └ <Process(Process-2, started)>
    │    │        │    └ ()
    │    │        └ <Process(Process-2, started)>
    │    └ <bound method Scheduler.run_getter of <proxypool.scheduler.Scheduler object at 0x00000158F2A7CB38>>
    └ <Process(Process-2, started)>

  File "E:\代理池\ProxyPool\proxypool\scheduler.py", line 48, in run_getter
    getter.run()
    │      └ <function Getter.run at 0x00000158F2643D08>
    └ <proxypool.processors.getter.Getter object at 0x00000158F10F1D30>

> File "E:\代理池\ProxyPool\proxypool\processors\getter.py", line 36, in run
    for proxy in crawler.crawl():
        │        │       └ <function BaseCrawler.crawl at 0x00000158F2643510>
        │        └ <public.kuaidaili.KuaidailiCrawler object at 0x00000158F2A7CD30>
        └ Proxy(host='1.197.204.242', port='9999')

  File "E:\代理池\ProxyPool\proxypool\crawlers\base.py", line 25, in crawl
    html = self.fetch(url)
    │      │    │     └ 'https://www.kuaidaili.com/free/inha/2/'
    │      │    └ <function BaseCrawler.fetch at 0x00000158F2643488>
    │      └ <public.kuaidaili.KuaidailiCrawler object at 0x00000158F2A7CD30>
    └ '<!DOCTYPE html>\n<html>\n<head>\n<meta http-equiv="X-UA-Compatible" content="IE=edge" />\n<meta http-equiv="Content-Type" co...

  File "D:\python37\lib\site-packages\retrying.py", line 49, in wrapped_f
    return Retrying(*dargs, **dkw).call(f, *args, **kw)
           │         │        │         │   │       └ {}
           │         │        │         │   └ (<public.kuaidaili.KuaidailiCrawler object at 0x00000158F2A7CD30>, 'https://www.kuaidaili.com/free/inha/2/')
           │         │        │         └ <function BaseCrawler.fetch at 0x00000158F2643400>
           │         │        └ {'stop_max_attempt_number': 3, 'retry_on_result': <function BaseCrawler.<lambda> at 0x00000158F22847B8>}
           │         └ ()
           └ <class 'retrying.Retrying'>
  File "D:\python37\lib\site-packages\retrying.py", line 214, in call
    raise RetryError(attempt)
          │          └ Attempts: 3, Value: None
          └ <class 'retrying.RetryError'>

retrying.RetryError: RetryError[Attempts: 3, Value: None]
2020-05-29 14:22:51.608 | ERROR    | proxypool.processors.getter:run:36 - An error has been caught in function 'run', process 'Process-2' (25504), thread 'MainThread' (27640):
Traceback (most recent call last):
  File "<string>", line 1, in <module>
  File "D:\python37\lib\multiprocessing\spawn.py", line 105, in spawn_main
    exitcode = _main(fd)
               │     └ 3
               └ <function _main at 0x00000158F1133EA0>
  File "D:\python37\lib\multiprocessing\spawn.py", line 118, in _main
    return self._bootstrap()
           │    └ <function BaseProcess._bootstrap at 0x00000158F10F78C8>
           └ <Process(Process-2, started)>
  File "D:\python37\lib\multiprocessing\process.py", line 297, in _bootstrap
    self.run()
    │    └ <function BaseProcess.run at 0x00000158F10E8F28>
    └ <Process(Process-2, started)>
  File "D:\python37\lib\multiprocessing\process.py", line 99, in run
    self._target(*self._args, **self._kwargs)
    │    │        │    │        │    └ {}
    │    │        │    │        └ <Process(Process-2, started)>
    │    │        │    └ ()
    │    │        └ <Process(Process-2, started)>
    │    └ <bound method Scheduler.run_getter of <proxypool.scheduler.Scheduler object at 0x00000158F2A7CB38>>
    └ <Process(Process-2, started)>

  File "E:\代理池\ProxyPool\proxypool\scheduler.py", line 48, in run_getter
    getter.run()
    │      └ <function Getter.run at 0x00000158F2643D08>
    └ <proxypool.processors.getter.Getter object at 0x00000158F10F1D30>

> File "E:\代理池\ProxyPool\proxypool\processors\getter.py", line 36, in run
    for proxy in crawler.crawl():
        │        │       └ <function BaseCrawler.crawl at 0x00000158F2643510>
        │        └ <public.kuaidaili.KuaidailiCrawler object at 0x00000158F2A7CD30>
        └ Proxy(host='1.197.204.242', port='9999')

  File "E:\代理池\ProxyPool\proxypool\crawlers\base.py", line 25, in crawl
    html = self.fetch(url)
    │      │    │     └ 'https://www.kuaidaili.com/free/inha/2/'
    │      │    └ <function BaseCrawler.fetch at 0x00000158F2643488>
    │      └ <public.kuaidaili.KuaidailiCrawler object at 0x00000158F2A7CD30>
    └ '<!DOCTYPE html>\n<html>\n<head>\n<meta http-equiv="X-UA-Compatible" content="IE=edge" />\n<meta http-equiv="Content-Type" co...

  File "D:\python37\lib\site-packages\retrying.py", line 49, in wrapped_f
    return Retrying(*dargs, **dkw).call(f, *args, **kw)
           │         │        │         │   │       └ {}
           │         │        │         │   └ (<public.kuaidaili.KuaidailiCrawler object at 0x00000158F2A7CD30>, 'https://www.kuaidaili.com/free/inha/2/')
           │         │        │         └ <function BaseCrawler.fetch at 0x00000158F2643400>
           │         │        └ {'stop_max_attempt_number': 3, 'retry_on_result': <function BaseCrawler.<lambda> at 0x00000158F22847B8>}
           │         └ ()
           └ <class 'retrying.Retrying'>
  File "D:\python37\lib\site-packages\retrying.py", line 214, in call
    raise RetryError(attempt)
          │          └ Attempts: 3, Value: None
          └ <class 'retrying.RetryError'>

retrying.RetryError: RetryError[Attempts: 3, Value: None]
2020-05-29 14:24:37.157 | ERROR    | proxypool.processors.getter:run:36 - An error has been caught in function 'run', process 'Process-2' (25504), thread 'MainThread' (27640):
Traceback (most recent call last):
  File "<string>", line 1, in <module>
  File "D:\python37\lib\multiprocessing\spawn.py", line 105, in spawn_main
    exitcode = _main(fd)
               │     └ 3
               └ <function _main at 0x00000158F1133EA0>
  File "D:\python37\lib\multiprocessing\spawn.py", line 118, in _main
    return self._bootstrap()
           │    └ <function BaseProcess._bootstrap at 0x00000158F10F78C8>
           └ <Process(Process-2, started)>
  File "D:\python37\lib\multiprocessing\process.py", line 297, in _bootstrap
    self.run()
    │    └ <function BaseProcess.run at 0x00000158F10E8F28>
    └ <Process(Process-2, started)>
  File "D:\python37\lib\multiprocessing\process.py", line 99, in run
    self._target(*self._args, **self._kwargs)
    │    │        │    │        │    └ {}
    │    │        │    │        └ <Process(Process-2, started)>
    │    │        │    └ ()
    │    │        └ <Process(Process-2, started)>
    │    └ <bound method Scheduler.run_getter of <proxypool.scheduler.Scheduler object at 0x00000158F2A7CB38>>
    └ <Process(Process-2, started)>

  File "E:\代理池\ProxyPool\proxypool\scheduler.py", line 48, in run_getter
    getter.run()
    │      └ <function Getter.run at 0x00000158F2643D08>
    └ <proxypool.processors.getter.Getter object at 0x00000158F10F1D30>

> File "E:\代理池\ProxyPool\proxypool\processors\getter.py", line 36, in run
    for proxy in crawler.crawl():
        │        │       └ <function BaseCrawler.crawl at 0x00000158F2643510>
        │        └ <public.kuaidaili.KuaidailiCrawler object at 0x00000158F2A7CD30>
        └ Proxy(host='1.197.204.242', port='9999')

  File "E:\代理池\ProxyPool\proxypool\crawlers\base.py", line 25, in crawl
    html = self.fetch(url)
    │      │    │     └ 'https://www.kuaidaili.com/free/inha/2/'
    │      │    └ <function BaseCrawler.fetch at 0x00000158F2643488>
    │      └ <public.kuaidaili.KuaidailiCrawler object at 0x00000158F2A7CD30>
    └ '<!DOCTYPE html>\n<html>\n<head>\n<meta http-equiv="X-UA-Compatible" content="IE=edge" />\n<meta http-equiv="Content-Type" co...

  File "D:\python37\lib\site-packages\retrying.py", line 49, in wrapped_f
    return Retrying(*dargs, **dkw).call(f, *args, **kw)
           │         │        │         │   │       └ {}
           │         │        │         │   └ (<public.kuaidaili.KuaidailiCrawler object at 0x00000158F2A7CD30>, 'https://www.kuaidaili.com/free/inha/2/')
           │         │        │         └ <function BaseCrawler.fetch at 0x00000158F2643400>
           │         │        └ {'stop_max_attempt_number': 3, 'retry_on_result': <function BaseCrawler.<lambda> at 0x00000158F22847B8>}
           │         └ ()
           └ <class 'retrying.Retrying'>
  File "D:\python37\lib\site-packages\retrying.py", line 214, in call
    raise RetryError(attempt)
          │          └ Attempts: 3, Value: None
          └ <class 'retrying.RetryError'>

retrying.RetryError: RetryError[Attempts: 3, Value: None]
2020-05-29 14:26:22.392 | ERROR    | proxypool.processors.getter:run:36 - An error has been caught in function 'run', process 'Process-2' (25504), thread 'MainThread' (27640):
Traceback (most recent call last):
  File "<string>", line 1, in <module>
  File "D:\python37\lib\multiprocessing\spawn.py", line 105, in spawn_main
    exitcode = _main(fd)
               │     └ 3
               └ <function _main at 0x00000158F1133EA0>
  File "D:\python37\lib\multiprocessing\spawn.py", line 118, in _main
    return self._bootstrap()
           │    └ <function BaseProcess._bootstrap at 0x00000158F10F78C8>
           └ <Process(Process-2, started)>
  File "D:\python37\lib\multiprocessing\process.py", line 297, in _bootstrap
    self.run()
    │    └ <function BaseProcess.run at 0x00000158F10E8F28>
    └ <Process(Process-2, started)>
  File "D:\python37\lib\multiprocessing\process.py", line 99, in run
    self._target(*self._args, **self._kwargs)
    │    │        │    │        │    └ {}
    │    │        │    │        └ <Process(Process-2, started)>
    │    │        │    └ ()
    │    │        └ <Process(Process-2, started)>
    │    └ <bound method Scheduler.run_getter of <proxypool.scheduler.Scheduler object at 0x00000158F2A7CB38>>
    └ <Process(Process-2, started)>

  File "E:\代理池\ProxyPool\proxypool\scheduler.py", line 48, in run_getter
    getter.run()
    │      └ <function Getter.run at 0x00000158F2643D08>
    └ <proxypool.processors.getter.Getter object at 0x00000158F10F1D30>

> File "E:\代理池\ProxyPool\proxypool\processors\getter.py", line 36, in run
    for proxy in crawler.crawl():
        │        │       └ <function BaseCrawler.crawl at 0x00000158F2643510>
        │        └ <public.kuaidaili.KuaidailiCrawler object at 0x00000158F2A7CD30>
        └ Proxy(host='1.197.204.242', port='9999')

  File "E:\代理池\ProxyPool\proxypool\crawlers\base.py", line 25, in crawl
    html = self.fetch(url)
    │      │    │     └ 'https://www.kuaidaili.com/free/inha/2/'
    │      │    └ <function BaseCrawler.fetch at 0x00000158F2643488>
    │      └ <public.kuaidaili.KuaidailiCrawler object at 0x00000158F2A7CD30>
    └ '<!DOCTYPE html>\n<html>\n<head>\n<meta http-equiv="X-UA-Compatible" content="IE=edge" />\n<meta http-equiv="Content-Type" co...

  File "D:\python37\lib\site-packages\retrying.py", line 49, in wrapped_f
    return Retrying(*dargs, **dkw).call(f, *args, **kw)
           │         │        │         │   │       └ {}
           │         │        │         │   └ (<public.kuaidaili.KuaidailiCrawler object at 0x00000158F2A7CD30>, 'https://www.kuaidaili.com/free/inha/2/')
           │         │        │         └ <function BaseCrawler.fetch at 0x00000158F2643400>
           │         │        └ {'stop_max_attempt_number': 3, 'retry_on_result': <function BaseCrawler.<lambda> at 0x00000158F22847B8>}
           │         └ ()
           └ <class 'retrying.Retrying'>
  File "D:\python37\lib\site-packages\retrying.py", line 214, in call
    raise RetryError(attempt)
          │          └ Attempts: 3, Value: None
          └ <class 'retrying.RetryError'>

retrying.RetryError: RetryError[Attempts: 3, Value: None]
2020-05-29 14:28:09.549 | ERROR    | proxypool.processors.getter:run:36 - An error has been caught in function 'run', process 'Process-2' (25504), thread 'MainThread' (27640):
Traceback (most recent call last):
  File "<string>", line 1, in <module>
  File "D:\python37\lib\multiprocessing\spawn.py", line 105, in spawn_main
    exitcode = _main(fd)
               │     └ 3
               └ <function _main at 0x00000158F1133EA0>
  File "D:\python37\lib\multiprocessing\spawn.py", line 118, in _main
    return self._bootstrap()
           │    └ <function BaseProcess._bootstrap at 0x00000158F10F78C8>
           └ <Process(Process-2, started)>
  File "D:\python37\lib\multiprocessing\process.py", line 297, in _bootstrap
    self.run()
    │    └ <function BaseProcess.run at 0x00000158F10E8F28>
    └ <Process(Process-2, started)>
  File "D:\python37\lib\multiprocessing\process.py", line 99, in run
    self._target(*self._args, **self._kwargs)
    │    │        │    │        │    └ {}
    │    │        │    │        └ <Process(Process-2, started)>
    │    │        │    └ ()
    │    │        └ <Process(Process-2, started)>
    │    └ <bound method Scheduler.run_getter of <proxypool.scheduler.Scheduler object at 0x00000158F2A7CB38>>
    └ <Process(Process-2, started)>

  File "E:\代理池\ProxyPool\proxypool\scheduler.py", line 48, in run_getter
    getter.run()
    │      └ <function Getter.run at 0x00000158F2643D08>
    └ <proxypool.processors.getter.Getter object at 0x00000158F10F1D30>

> File "E:\代理池\ProxyPool\proxypool\processors\getter.py", line 36, in run
    for proxy in crawler.crawl():
        │        │       └ <function BaseCrawler.crawl at 0x00000158F2643510>
        │        └ <public.kuaidaili.KuaidailiCrawler object at 0x00000158F2A7CD30>
        └ Proxy(host='1.197.204.242', port='9999')

  File "E:\代理池\ProxyPool\proxypool\crawlers\base.py", line 25, in crawl
    html = self.fetch(url)
    │      │    │     └ 'https://www.kuaidaili.com/free/inha/2/'
    │      │    └ <function BaseCrawler.fetch at 0x00000158F2643488>
    │      └ <public.kuaidaili.KuaidailiCrawler object at 0x00000158F2A7CD30>
    └ '<!DOCTYPE html>\n<html>\n<head>\n<meta http-equiv="X-UA-Compatible" content="IE=edge" />\n<meta http-equiv="Content-Type" co...

  File "D:\python37\lib\site-packages\retrying.py", line 49, in wrapped_f
    return Retrying(*dargs, **dkw).call(f, *args, **kw)
           │         │        │         │   │       └ {}
           │         │        │         │   └ (<public.kuaidaili.KuaidailiCrawler object at 0x00000158F2A7CD30>, 'https://www.kuaidaili.com/free/inha/2/')
           │         │        │         └ <function BaseCrawler.fetch at 0x00000158F2643400>
           │         │        └ {'stop_max_attempt_number': 3, 'retry_on_result': <function BaseCrawler.<lambda> at 0x00000158F22847B8>}
           │         └ ()
           └ <class 'retrying.Retrying'>
  File "D:\python37\lib\site-packages\retrying.py", line 214, in call
    raise RetryError(attempt)
          │          └ Attempts: 3, Value: None
          └ <class 'retrying.RetryError'>

retrying.RetryError: RetryError[Attempts: 3, Value: None]
2020-05-29 14:52:39.943 | ERROR    | proxypool.scheduler:run_tester:33 - An error has been caught in function 'run_tester', process 'Process-1' (26968), thread 'MainThread' (27548):
Traceback (most recent call last):
  File "<string>", line 1, in <module>
  File "D:\python37\lib\multiprocessing\spawn.py", line 105, in spawn_main
    exitcode = _main(fd)
               │     └ 3
               └ <function _main at 0x00000258471C4EA0>
  File "D:\python37\lib\multiprocessing\spawn.py", line 118, in _main
    return self._bootstrap()
           │    └ <function BaseProcess._bootstrap at 0x00000258471878C8>
           └ <Process(Process-1, started)>
  File "D:\python37\lib\multiprocessing\process.py", line 297, in _bootstrap
    self.run()
    │    └ <function BaseProcess.run at 0x0000025847178F28>
    └ <Process(Process-1, started)>
  File "D:\python37\lib\multiprocessing\process.py", line 99, in run
    self._target(*self._args, **self._kwargs)
    │    │        │    │        │    └ {}
    │    │        │    │        └ <Process(Process-1, started)>
    │    │        │    └ ()
    │    │        └ <Process(Process-1, started)>
    │    └ <bound method Scheduler.run_tester of <proxypool.scheduler.Scheduler object at 0x0000025848B0CC88>>
    └ <Process(Process-1, started)>

> File "E:\代理池\ProxyPool\proxypool\scheduler.py", line 33, in run_tester
    tester.run()
    │      └ <function Tester.run at 0x0000025848B23400>
    └ <proxypool.processors.tester.Tester object at 0x0000025847181C88>

  File "E:\代理池\ProxyPool\proxypool\processors\tester.py", line 69, in run
    tasks = [self.test(proxy) for proxy in proxies]
    │        │    │                        └ None
    │        │    └ <function Tester.test at 0x0000025848B0EF28>
    │        └ <proxypool.processors.tester.Tester object at 0x0000025847181C88>
    └ [<coroutine object Tester.test at 0x0000025848C6B7C8>, <coroutine object Tester.test at 0x0000025848C6BC48>, <coroutine objec...

TypeError: 'NoneType' object is not iterable
2020-05-29 14:58:40.945 | ERROR    | proxypool.scheduler:run_tester:33 - An error has been caught in function 'run_tester', process 'Process-1' (26968), thread 'MainThread' (27548):
Traceback (most recent call last):
  File "<string>", line 1, in <module>
  File "D:\python37\lib\multiprocessing\spawn.py", line 105, in spawn_main
    exitcode = _main(fd)
               │     └ 3
               └ <function _main at 0x00000258471C4EA0>
  File "D:\python37\lib\multiprocessing\spawn.py", line 118, in _main
    return self._bootstrap()
           │    └ <function BaseProcess._bootstrap at 0x00000258471878C8>
           └ <Process(Process-1, started)>
  File "D:\python37\lib\multiprocessing\process.py", line 297, in _bootstrap
    self.run()
    │    └ <function BaseProcess.run at 0x0000025847178F28>
    └ <Process(Process-1, started)>
  File "D:\python37\lib\multiprocessing\process.py", line 99, in run
    self._target(*self._args, **self._kwargs)
    │    │        │    │        │    └ {}
    │    │        │    │        └ <Process(Process-1, started)>
    │    │        │    └ ()
    │    │        └ <Process(Process-1, started)>
    │    └ <bound method Scheduler.run_tester of <proxypool.scheduler.Scheduler object at 0x0000025848B0CC88>>
    └ <Process(Process-1, started)>

> File "E:\代理池\ProxyPool\proxypool\scheduler.py", line 33, in run_tester
    tester.run()
    │      └ <function Tester.run at 0x0000025848B23400>
    └ <proxypool.processors.tester.Tester object at 0x0000025847181C88>

  File "E:\代理池\ProxyPool\proxypool\processors\tester.py", line 69, in run
    tasks = [self.test(proxy) for proxy in proxies]
    │        │    │                        └ None
    │        │    └ <function Tester.test at 0x0000025848B0EF28>
    │        └ <proxypool.processors.tester.Tester object at 0x0000025847181C88>
    └ [<coroutine object Tester.test at 0x0000025848A91F48>, <coroutine object Tester.test at 0x0000025848B950C8>, <coroutine objec...

TypeError: 'NoneType' object is not iterable
2020-05-29 15:04:30.925 | ERROR    | proxypool.scheduler:run_tester:33 - An error has been caught in function 'run_tester', process 'Process-1' (26968), thread 'MainThread' (27548):
Traceback (most recent call last):
  File "<string>", line 1, in <module>
  File "D:\python37\lib\multiprocessing\spawn.py", line 105, in spawn_main
    exitcode = _main(fd)
               │     └ 3
               └ <function _main at 0x00000258471C4EA0>
  File "D:\python37\lib\multiprocessing\spawn.py", line 118, in _main
    return self._bootstrap()
           │    └ <function BaseProcess._bootstrap at 0x00000258471878C8>
           └ <Process(Process-1, started)>
  File "D:\python37\lib\multiprocessing\process.py", line 297, in _bootstrap
    self.run()
    │    └ <function BaseProcess.run at 0x0000025847178F28>
    └ <Process(Process-1, started)>
  File "D:\python37\lib\multiprocessing\process.py", line 99, in run
    self._target(*self._args, **self._kwargs)
    │    │        │    │        │    └ {}
    │    │        │    │        └ <Process(Process-1, started)>
    │    │        │    └ ()
    │    │        └ <Process(Process-1, started)>
    │    └ <bound method Scheduler.run_tester of <proxypool.scheduler.Scheduler object at 0x0000025848B0CC88>>
    └ <Process(Process-1, started)>

> File "E:\代理池\ProxyPool\proxypool\scheduler.py", line 33, in run_tester
    tester.run()
    │      └ <function Tester.run at 0x0000025848B23400>
    └ <proxypool.processors.tester.Tester object at 0x0000025847181C88>

  File "E:\代理池\ProxyPool\proxypool\processors\tester.py", line 69, in run
    tasks = [self.test(proxy) for proxy in proxies]
    │        │    │                        └ None
    │        │    └ <function Tester.test at 0x0000025848B0EF28>
    │        └ <proxypool.processors.tester.Tester object at 0x0000025847181C88>
    └ [<coroutine object Tester.test at 0x0000025848B584C8>]

TypeError: 'NoneType' object is not iterable
2020-05-29 15:09:47.959 | ERROR    | proxypool.scheduler:run_tester:33 - An error has been caught in function 'run_tester', process 'Process-1' (26968), thread 'MainThread' (27548):
Traceback (most recent call last):
  File "<string>", line 1, in <module>
  File "D:\python37\lib\multiprocessing\spawn.py", line 105, in spawn_main
    exitcode = _main(fd)
               │     └ 3
               └ <function _main at 0x00000258471C4EA0>
  File "D:\python37\lib\multiprocessing\spawn.py", line 118, in _main
    return self._bootstrap()
           │    └ <function BaseProcess._bootstrap at 0x00000258471878C8>
           └ <Process(Process-1, started)>
  File "D:\python37\lib\multiprocessing\process.py", line 297, in _bootstrap
    self.run()
    │    └ <function BaseProcess.run at 0x0000025847178F28>
    └ <Process(Process-1, started)>
  File "D:\python37\lib\multiprocessing\process.py", line 99, in run
    self._target(*self._args, **self._kwargs)
    │    │        │    │        │    └ {}
    │    │        │    │        └ <Process(Process-1, started)>
    │    │        │    └ ()
    │    │        └ <Process(Process-1, started)>
    │    └ <bound method Scheduler.run_tester of <proxypool.scheduler.Scheduler object at 0x0000025848B0CC88>>
    └ <Process(Process-1, started)>

> File "E:\代理池\ProxyPool\proxypool\scheduler.py", line 33, in run_tester
    tester.run()
    │      └ <function Tester.run at 0x0000025848B23400>
    └ <proxypool.processors.tester.Tester object at 0x0000025847181C88>

  File "E:\代理池\ProxyPool\proxypool\processors\tester.py", line 69, in run
    tasks = [self.test(proxy) for proxy in proxies]
    │        │    │                        └ None
    │        │    └ <function Tester.test at 0x0000025848B0EF28>
    │        └ <proxypool.processors.tester.Tester object at 0x0000025847181C88>
    └ [<coroutine object Tester.test at 0x0000025848C598C8>, <coroutine object Tester.test at 0x0000025848C59848>, <coroutine objec...

TypeError: 'NoneType' object is not iterable
2020-05-29 15:14:31.946 | ERROR    | proxypool.scheduler:run_tester:33 - An error has been caught in function 'run_tester', process 'Process-1' (26968), thread 'MainThread' (27548):
Traceback (most recent call last):
  File "<string>", line 1, in <module>
  File "D:\python37\lib\multiprocessing\spawn.py", line 105, in spawn_main
    exitcode = _main(fd)
               │     └ 3
               └ <function _main at 0x00000258471C4EA0>
  File "D:\python37\lib\multiprocessing\spawn.py", line 118, in _main
    return self._bootstrap()
           │    └ <function BaseProcess._bootstrap at 0x00000258471878C8>
           └ <Process(Process-1, started)>
  File "D:\python37\lib\multiprocessing\process.py", line 297, in _bootstrap
    self.run()
    │    └ <function BaseProcess.run at 0x0000025847178F28>
    └ <Process(Process-1, started)>
  File "D:\python37\lib\multiprocessing\process.py", line 99, in run
    self._target(*self._args, **self._kwargs)
    │    │        │    │        │    └ {}
    │    │        │    │        └ <Process(Process-1, started)>
    │    │        │    └ ()
    │    │        └ <Process(Process-1, started)>
    │    └ <bound method Scheduler.run_tester of <proxypool.scheduler.Scheduler object at 0x0000025848B0CC88>>
    └ <Process(Process-1, started)>

> File "E:\代理池\ProxyPool\proxypool\scheduler.py", line 33, in run_tester
    tester.run()
    │      └ <function Tester.run at 0x0000025848B23400>
    └ <proxypool.processors.tester.Tester object at 0x0000025847181C88>

  File "E:\代理池\ProxyPool\proxypool\processors\tester.py", line 69, in run
    tasks = [self.test(proxy) for proxy in proxies]
    │        │    │                        └ None
    │        │    └ <function Tester.test at 0x0000025848B0EF28>
    │        └ <proxypool.processors.tester.Tester object at 0x0000025847181C88>
    └ [<coroutine object Tester.test at 0x0000025848B59848>, <coroutine object Tester.test at 0x0000025848B597C8>, <coroutine objec...

TypeError: 'NoneType' object is not iterable
2020-05-29 15:18:44.106 | ERROR    | proxypool.scheduler:run_tester:33 - An error has been caught in function 'run_tester', process 'Process-1' (26968), thread 'MainThread' (27548):
Traceback (most recent call last):
  File "<string>", line 1, in <module>
  File "D:\python37\lib\multiprocessing\spawn.py", line 105, in spawn_main
    exitcode = _main(fd)
               │     └ 3
               └ <function _main at 0x00000258471C4EA0>
  File "D:\python37\lib\multiprocessing\spawn.py", line 118, in _main
    return self._bootstrap()
           │    └ <function BaseProcess._bootstrap at 0x00000258471878C8>
           └ <Process(Process-1, started)>
  File "D:\python37\lib\multiprocessing\process.py", line 297, in _bootstrap
    self.run()
    │    └ <function BaseProcess.run at 0x0000025847178F28>
    └ <Process(Process-1, started)>
  File "D:\python37\lib\multiprocessing\process.py", line 99, in run
    self._target(*self._args, **self._kwargs)
    │    │        │    │        │    └ {}
    │    │        │    │        └ <Process(Process-1, started)>
    │    │        │    └ ()
    │    │        └ <Process(Process-1, started)>
    │    └ <bound method Scheduler.run_tester of <proxypool.scheduler.Scheduler object at 0x0000025848B0CC88>>
    └ <Process(Process-1, started)>

> File "E:\代理池\ProxyPool\proxypool\scheduler.py", line 33, in run_tester
    tester.run()
    │      └ <function Tester.run at 0x0000025848B23400>
    └ <proxypool.processors.tester.Tester object at 0x0000025847181C88>

  File "E:\代理池\ProxyPool\proxypool\processors\tester.py", line 69, in run
    tasks = [self.test(proxy) for proxy in proxies]
    │        │    │                        └ None
    │        │    └ <function Tester.test at 0x0000025848B0EF28>
    │        └ <proxypool.processors.tester.Tester object at 0x0000025847181C88>
    └ [<coroutine object Tester.test at 0x0000025848C6A3C8>]

TypeError: 'NoneType' object is not iterable
2020-05-29 15:22:32.953 | ERROR    | proxypool.scheduler:run_tester:33 - An error has been caught in function 'run_tester', process 'Process-1' (26968), thread 'MainThread' (27548):
Traceback (most recent call last):
  File "<string>", line 1, in <module>
  File "D:\python37\lib\multiprocessing\spawn.py", line 105, in spawn_main
    exitcode = _main(fd)
               │     └ 3
               └ <function _main at 0x00000258471C4EA0>
  File "D:\python37\lib\multiprocessing\spawn.py", line 118, in _main
    return self._bootstrap()
           │    └ <function BaseProcess._bootstrap at 0x00000258471878C8>
           └ <Process(Process-1, started)>
  File "D:\python37\lib\multiprocessing\process.py", line 297, in _bootstrap
    self.run()
    │    └ <function BaseProcess.run at 0x0000025847178F28>
    └ <Process(Process-1, started)>
  File "D:\python37\lib\multiprocessing\process.py", line 99, in run
    self._target(*self._args, **self._kwargs)
    │    │        │    │        │    └ {}
    │    │        │    │        └ <Process(Process-1, started)>
    │    │        │    └ ()
    │    │        └ <Process(Process-1, started)>
    │    └ <bound method Scheduler.run_tester of <proxypool.scheduler.Scheduler object at 0x0000025848B0CC88>>
    └ <Process(Process-1, started)>

> File "E:\代理池\ProxyPool\proxypool\scheduler.py", line 33, in run_tester
    tester.run()
    │      └ <function Tester.run at 0x0000025848B23400>
    └ <proxypool.processors.tester.Tester object at 0x0000025847181C88>

  File "E:\代理池\ProxyPool\proxypool\processors\tester.py", line 69, in run
    tasks = [self.test(proxy) for proxy in proxies]
    │        │    │                        └ None
    │        │    └ <function Tester.test at 0x0000025848B0EF28>
    │        └ <proxypool.processors.tester.Tester object at 0x0000025847181C88>
    └ [<coroutine object Tester.test at 0x0000025848B49348>, <coroutine object Tester.test at 0x0000025848B49648>, <coroutine objec...

TypeError: 'NoneType' object is not iterable
2020-05-29 15:26:01.287 | ERROR    | proxypool.scheduler:run_tester:33 - An error has been caught in function 'run_tester', process 'Process-1' (26968), thread 'MainThread' (27548):
Traceback (most recent call last):
  File "<string>", line 1, in <module>
  File "D:\python37\lib\multiprocessing\spawn.py", line 105, in spawn_main
    exitcode = _main(fd)
               │     └ 3
               └ <function _main at 0x00000258471C4EA0>
  File "D:\python37\lib\multiprocessing\spawn.py", line 118, in _main
    return self._bootstrap()
           │    └ <function BaseProcess._bootstrap at 0x00000258471878C8>
           └ <Process(Process-1, started)>
  File "D:\python37\lib\multiprocessing\process.py", line 297, in _bootstrap
    self.run()
    │    └ <function BaseProcess.run at 0x0000025847178F28>
    └ <Process(Process-1, started)>
  File "D:\python37\lib\multiprocessing\process.py", line 99, in run
    self._target(*self._args, **self._kwargs)
    │    │        │    │        │    └ {}
    │    │        │    │        └ <Process(Process-1, started)>
    │    │        │    └ ()
    │    │        └ <Process(Process-1, started)>
    │    └ <bound method Scheduler.run_tester of <proxypool.scheduler.Scheduler object at 0x0000025848B0CC88>>
    └ <Process(Process-1, started)>

> File "E:\代理池\ProxyPool\proxypool\scheduler.py", line 33, in run_tester
    tester.run()
    │      └ <function Tester.run at 0x0000025848B23400>
    └ <proxypool.processors.tester.Tester object at 0x0000025847181C88>

  File "E:\代理池\ProxyPool\proxypool\processors\tester.py", line 69, in run
    tasks = [self.test(proxy) for proxy in proxies]
    │        │    │                        └ None
    │        │    └ <function Tester.test at 0x0000025848B0EF28>
    │        └ <proxypool.processors.tester.Tester object at 0x0000025847181C88>
    └ [<coroutine object Tester.test at 0x0000025847161E48>, <coroutine object Tester.test at 0x0000025848AF3BC8>, <coroutine objec...

TypeError: 'NoneType' object is not iterable
2020-05-29 15:29:16.940 | ERROR    | proxypool.scheduler:run_tester:33 - An error has been caught in function 'run_tester', process 'Process-1' (26968), thread 'MainThread' (27548):
Traceback (most recent call last):
  File "<string>", line 1, in <module>
  File "D:\python37\lib\multiprocessing\spawn.py", line 105, in spawn_main
    exitcode = _main(fd)
               │     └ 3
               └ <function _main at 0x00000258471C4EA0>
  File "D:\python37\lib\multiprocessing\spawn.py", line 118, in _main
    return self._bootstrap()
           │    └ <function BaseProcess._bootstrap at 0x00000258471878C8>
           └ <Process(Process-1, started)>
  File "D:\python37\lib\multiprocessing\process.py", line 297, in _bootstrap
    self.run()
    │    └ <function BaseProcess.run at 0x0000025847178F28>
    └ <Process(Process-1, started)>
  File "D:\python37\lib\multiprocessing\process.py", line 99, in run
    self._target(*self._args, **self._kwargs)
    │    │        │    │        │    └ {}
    │    │        │    │        └ <Process(Process-1, started)>
    │    │        │    └ ()
    │    │        └ <Process(Process-1, started)>
    │    └ <bound method Scheduler.run_tester of <proxypool.scheduler.Scheduler object at 0x0000025848B0CC88>>
    └ <Process(Process-1, started)>

> File "E:\代理池\ProxyPool\proxypool\scheduler.py", line 33, in run_tester
    tester.run()
    │      └ <function Tester.run at 0x0000025848B23400>
    └ <proxypool.processors.tester.Tester object at 0x0000025847181C88>

  File "E:\代理池\ProxyPool\proxypool\processors\tester.py", line 69, in run
    tasks = [self.test(proxy) for proxy in proxies]
    │        │    │                        └ None
    │        │    └ <function Tester.test at 0x0000025848B0EF28>
    │        └ <proxypool.processors.tester.Tester object at 0x0000025847181C88>
    └ [<coroutine object Tester.test at 0x0000025848C34C48>, <coroutine object Tester.test at 0x0000025848C34BC8>, <coroutine objec...

TypeError: 'NoneType' object is not iterable
2020-05-29 15:32:10.942 | ERROR    | proxypool.scheduler:run_tester:33 - An error has been caught in function 'run_tester', process 'Process-1' (26968), thread 'MainThread' (27548):
Traceback (most recent call last):
  File "<string>", line 1, in <module>
  File "D:\python37\lib\multiprocessing\spawn.py", line 105, in spawn_main
    exitcode = _main(fd)
               │     └ 3
               └ <function _main at 0x00000258471C4EA0>
  File "D:\python37\lib\multiprocessing\spawn.py", line 118, in _main
    return self._bootstrap()
           │    └ <function BaseProcess._bootstrap at 0x00000258471878C8>
           └ <Process(Process-1, started)>
  File "D:\python37\lib\multiprocessing\process.py", line 297, in _bootstrap
    self.run()
    │    └ <function BaseProcess.run at 0x0000025847178F28>
    └ <Process(Process-1, started)>
  File "D:\python37\lib\multiprocessing\process.py", line 99, in run
    self._target(*self._args, **self._kwargs)
    │    │        │    │        │    └ {}
    │    │        │    │        └ <Process(Process-1, started)>
    │    │        │    └ ()
    │    │        └ <Process(Process-1, started)>
    │    └ <bound method Scheduler.run_tester of <proxypool.scheduler.Scheduler object at 0x0000025848B0CC88>>
    └ <Process(Process-1, started)>

> File "E:\代理池\ProxyPool\proxypool\scheduler.py", line 33, in run_tester
    tester.run()
    │      └ <function Tester.run at 0x0000025848B23400>
    └ <proxypool.processors.tester.Tester object at 0x0000025847181C88>

  File "E:\代理池\ProxyPool\proxypool\processors\tester.py", line 69, in run
    tasks = [self.test(proxy) for proxy in proxies]
    │        │    │                        └ None
    │        │    └ <function Tester.test at 0x0000025848B0EF28>
    │        └ <proxypool.processors.tester.Tester object at 0x0000025847181C88>
    └ [<coroutine object Tester.test at 0x0000025848B6F6C8>, <coroutine object Tester.test at 0x0000025848B6FD48>, <coroutine objec...

TypeError: 'NoneType' object is not iterable
2020-05-29 15:34:53.939 | ERROR    | proxypool.scheduler:run_tester:33 - An error has been caught in function 'run_tester', process 'Process-1' (26968), thread 'MainThread' (27548):
Traceback (most recent call last):
  File "<string>", line 1, in <module>
  File "D:\python37\lib\multiprocessing\spawn.py", line 105, in spawn_main
    exitcode = _main(fd)
               │     └ 3
               └ <function _main at 0x00000258471C4EA0>
  File "D:\python37\lib\multiprocessing\spawn.py", line 118, in _main
    return self._bootstrap()
           │    └ <function BaseProcess._bootstrap at 0x00000258471878C8>
           └ <Process(Process-1, started)>
  File "D:\python37\lib\multiprocessing\process.py", line 297, in _bootstrap
    self.run()
    │    └ <function BaseProcess.run at 0x0000025847178F28>
    └ <Process(Process-1, started)>
  File "D:\python37\lib\multiprocessing\process.py", line 99, in run
    self._target(*self._args, **self._kwargs)
    │    │        │    │        │    └ {}
    │    │        │    │        └ <Process(Process-1, started)>
    │    │        │    └ ()
    │    │        └ <Process(Process-1, started)>
    │    └ <bound method Scheduler.run_tester of <proxypool.scheduler.Scheduler object at 0x0000025848B0CC88>>
    └ <Process(Process-1, started)>

> File "E:\代理池\ProxyPool\proxypool\scheduler.py", line 33, in run_tester
    tester.run()
    │      └ <function Tester.run at 0x0000025848B23400>
    └ <proxypool.processors.tester.Tester object at 0x0000025847181C88>

  File "E:\代理池\ProxyPool\proxypool\processors\tester.py", line 69, in run
    tasks = [self.test(proxy) for proxy in proxies]
    │        │    │                        └ None
    │        │    └ <function Tester.test at 0x0000025848B0EF28>
    │        └ <proxypool.processors.tester.Tester object at 0x0000025847181C88>
    └ [<coroutine object Tester.test at 0x0000025848B49848>, <coroutine object Tester.test at 0x0000025848B49AC8>, <coroutine objec...

TypeError: 'NoneType' object is not iterable
2020-05-29 15:37:25.955 | ERROR    | proxypool.scheduler:run_tester:33 - An error has been caught in function 'run_tester', process 'Process-1' (26968), thread 'MainThread' (27548):
Traceback (most recent call last):
  File "<string>", line 1, in <module>
  File "D:\python37\lib\multiprocessing\spawn.py", line 105, in spawn_main
    exitcode = _main(fd)
               │     └ 3
               └ <function _main at 0x00000258471C4EA0>
  File "D:\python37\lib\multiprocessing\spawn.py", line 118, in _main
    return self._bootstrap()
           │    └ <function BaseProcess._bootstrap at 0x00000258471878C8>
           └ <Process(Process-1, started)>
  File "D:\python37\lib\multiprocessing\process.py", line 297, in _bootstrap
    self.run()
    │    └ <function BaseProcess.run at 0x0000025847178F28>
    └ <Process(Process-1, started)>
  File "D:\python37\lib\multiprocessing\process.py", line 99, in run
    self._target(*self._args, **self._kwargs)
    │    │        │    │        │    └ {}
    │    │        │    │        └ <Process(Process-1, started)>
    │    │        │    └ ()
    │    │        └ <Process(Process-1, started)>
    │    └ <bound method Scheduler.run_tester of <proxypool.scheduler.Scheduler object at 0x0000025848B0CC88>>
    └ <Process(Process-1, started)>

> File "E:\代理池\ProxyPool\proxypool\scheduler.py", line 33, in run_tester
    tester.run()
    │      └ <function Tester.run at 0x0000025848B23400>
    └ <proxypool.processors.tester.Tester object at 0x0000025847181C88>

  File "E:\代理池\ProxyPool\proxypool\processors\tester.py", line 69, in run
    tasks = [self.test(proxy) for proxy in proxies]
    │        │    │                        └ None
    │        │    └ <function Tester.test at 0x0000025848B0EF28>
    │        └ <proxypool.processors.tester.Tester object at 0x0000025847181C88>
    └ [<coroutine object Tester.test at 0x0000025848A91F48>, <coroutine object Tester.test at 0x0000025848715C48>, <coroutine objec...

TypeError: 'NoneType' object is not iterable
2020-05-29 15:39:46.943 | ERROR    | proxypool.scheduler:run_tester:33 - An error has been caught in function 'run_tester', process 'Process-1' (26968), thread 'MainThread' (27548):
Traceback (most recent call last):
  File "<string>", line 1, in <module>
  File "D:\python37\lib\multiprocessing\spawn.py", line 105, in spawn_main
    exitcode = _main(fd)
               │     └ 3
               └ <function _main at 0x00000258471C4EA0>
  File "D:\python37\lib\multiprocessing\spawn.py", line 118, in _main
    return self._bootstrap()
           │    └ <function BaseProcess._bootstrap at 0x00000258471878C8>
           └ <Process(Process-1, started)>
  File "D:\python37\lib\multiprocessing\process.py", line 297, in _bootstrap
    self.run()
    │    └ <function BaseProcess.run at 0x0000025847178F28>
    └ <Process(Process-1, started)>
  File "D:\python37\lib\multiprocessing\process.py", line 99, in run
    self._target(*self._args, **self._kwargs)
    │    │        │    │        │    └ {}
    │    │        │    │        └ <Process(Process-1, started)>
    │    │        │    └ ()
    │    │        └ <Process(Process-1, started)>
    │    └ <bound method Scheduler.run_tester of <proxypool.scheduler.Scheduler object at 0x0000025848B0CC88>>
    └ <Process(Process-1, started)>

> File "E:\代理池\ProxyPool\proxypool\scheduler.py", line 33, in run_tester
    tester.run()
    │      └ <function Tester.run at 0x0000025848B23400>
    └ <proxypool.processors.tester.Tester object at 0x0000025847181C88>

  File "E:\代理池\ProxyPool\proxypool\processors\tester.py", line 69, in run
    tasks = [self.test(proxy) for proxy in proxies]
    │        │    │                        └ None
    │        │    └ <function Tester.test at 0x0000025848B0EF28>
    │        └ <proxypool.processors.tester.Tester object at 0x0000025847181C88>
    └ [<coroutine object Tester.test at 0x0000025848AE68C8>, <coroutine object Tester.test at 0x0000025848AE6F48>, <coroutine objec...

TypeError: 'NoneType' object is not iterable
2020-05-29 15:58:36.671 | ERROR    | proxypool.processors.getter:run:36 - An error has been caught in function 'run', process 'Process-2' (19812), thread 'MainThread' (6168):
Traceback (most recent call last):
  File "<string>", line 1, in <module>
  File "D:\python37\lib\multiprocessing\spawn.py", line 105, in spawn_main
    exitcode = _main(fd)
               │     └ 3
               └ <function _main at 0x0000020678604EA0>
  File "D:\python37\lib\multiprocessing\spawn.py", line 118, in _main
    return self._bootstrap()
           │    └ <function BaseProcess._bootstrap at 0x00000206785C78C8>
           └ <Process(Process-2, started)>
  File "D:\python37\lib\multiprocessing\process.py", line 297, in _bootstrap
    self.run()
    │    └ <function BaseProcess.run at 0x00000206785B8F28>
    └ <Process(Process-2, started)>
  File "D:\python37\lib\multiprocessing\process.py", line 99, in run
    self._target(*self._args, **self._kwargs)
    │    │        │    │        │    └ {}
    │    │        │    │        └ <Process(Process-2, started)>
    │    │        │    └ ()
    │    │        └ <Process(Process-2, started)>
    │    └ <bound method Scheduler.run_getter of <proxypool.scheduler.Scheduler object at 0x0000020679F4BCC0>>
    └ <Process(Process-2, started)>

  File "E:\代理池\ProxyPool\proxypool\scheduler.py", line 48, in run_getter
    getter.run()
    │      └ <function Getter.run at 0x0000020679B13D08>
    └ <proxypool.processors.getter.Getter object at 0x00000206785C1E48>

> File "E:\代理池\ProxyPool\proxypool\processors\getter.py", line 36, in run
    for proxy in crawler.crawl():
        │        │       └ <function BaseCrawler.crawl at 0x0000020679B13510>
        │        └ <public.kuaidaili.KuaidailiCrawler object at 0x0000020679F4BC88>
        └ Proxy(host='175.155.139.172', port='1133')

  File "E:\代理池\ProxyPool\proxypool\crawlers\base.py", line 25, in crawl
    html = self.fetch(url)
    │      │    │     └ 'https://www.kuaidaili.com/free/inha/2/'
    │      │    └ <function BaseCrawler.fetch at 0x0000020679B13488>
    │      └ <public.kuaidaili.KuaidailiCrawler object at 0x0000020679F4BC88>
    └ '<!DOCTYPE html>\n<html>\n<head>\n<meta http-equiv="X-UA-Compatible" content="IE=edge" />\n<meta http-equiv="Content-Type" co...

  File "D:\python37\lib\site-packages\retrying.py", line 49, in wrapped_f
    return Retrying(*dargs, **dkw).call(f, *args, **kw)
           │         │        │         │   │       └ {}
           │         │        │         │   └ (<public.kuaidaili.KuaidailiCrawler object at 0x0000020679F4BC88>, 'https://www.kuaidaili.com/free/inha/2/')
           │         │        │         └ <function BaseCrawler.fetch at 0x0000020679B13400>
           │         │        └ {'stop_max_attempt_number': 3, 'retry_on_result': <function BaseCrawler.<lambda> at 0x00000206797547B8>}
           │         └ ()
           └ <class 'retrying.Retrying'>
  File "D:\python37\lib\site-packages\retrying.py", line 214, in call
    raise RetryError(attempt)
          │          └ Attempts: 3, Value: None
          └ <class 'retrying.RetryError'>

retrying.RetryError: RetryError[Attempts: 3, Value: None]
2020-05-29 16:00:29.516 | ERROR    | proxypool.processors.getter:run:36 - An error has been caught in function 'run', process 'Process-2' (19812), thread 'MainThread' (6168):
Traceback (most recent call last):
  File "<string>", line 1, in <module>
  File "D:\python37\lib\multiprocessing\spawn.py", line 105, in spawn_main
    exitcode = _main(fd)
               │     └ 3
               └ <function _main at 0x0000020678604EA0>
  File "D:\python37\lib\multiprocessing\spawn.py", line 118, in _main
    return self._bootstrap()
           │    └ <function BaseProcess._bootstrap at 0x00000206785C78C8>
           └ <Process(Process-2, started)>
  File "D:\python37\lib\multiprocessing\process.py", line 297, in _bootstrap
    self.run()
    │    └ <function BaseProcess.run at 0x00000206785B8F28>
    └ <Process(Process-2, started)>
  File "D:\python37\lib\multiprocessing\process.py", line 99, in run
    self._target(*self._args, **self._kwargs)
    │    │        │    │        │    └ {}
    │    │        │    │        └ <Process(Process-2, started)>
    │    │        │    └ ()
    │    │        └ <Process(Process-2, started)>
    │    └ <bound method Scheduler.run_getter of <proxypool.scheduler.Scheduler object at 0x0000020679F4BCC0>>
    └ <Process(Process-2, started)>

  File "E:\代理池\ProxyPool\proxypool\scheduler.py", line 48, in run_getter
    getter.run()
    │      └ <function Getter.run at 0x0000020679B13D08>
    └ <proxypool.processors.getter.Getter object at 0x00000206785C1E48>

> File "E:\代理池\ProxyPool\proxypool\processors\getter.py", line 36, in run
    for proxy in crawler.crawl():
        │        │       └ <function BaseCrawler.crawl at 0x0000020679B13510>
        │        └ <public.kuaidaili.KuaidailiCrawler object at 0x0000020679F4BC88>
        └ Proxy(host='175.155.139.172', port='1133')

  File "E:\代理池\ProxyPool\proxypool\crawlers\base.py", line 25, in crawl
    html = self.fetch(url)
    │      │    │     └ 'https://www.kuaidaili.com/free/inha/2/'
    │      │    └ <function BaseCrawler.fetch at 0x0000020679B13488>
    │      └ <public.kuaidaili.KuaidailiCrawler object at 0x0000020679F4BC88>
    └ '<!DOCTYPE html>\n<html>\n<head>\n<meta http-equiv="X-UA-Compatible" content="IE=edge" />\n<meta http-equiv="Content-Type" co...

  File "D:\python37\lib\site-packages\retrying.py", line 49, in wrapped_f
    return Retrying(*dargs, **dkw).call(f, *args, **kw)
           │         │        │         │   │       └ {}
           │         │        │         │   └ (<public.kuaidaili.KuaidailiCrawler object at 0x0000020679F4BC88>, 'https://www.kuaidaili.com/free/inha/2/')
           │         │        │         └ <function BaseCrawler.fetch at 0x0000020679B13400>
           │         │        └ {'stop_max_attempt_number': 3, 'retry_on_result': <function BaseCrawler.<lambda> at 0x00000206797547B8>}
           │         └ ()
           └ <class 'retrying.Retrying'>
  File "D:\python37\lib\site-packages\retrying.py", line 214, in call
    raise RetryError(attempt)
          │          └ Attempts: 3, Value: None
          └ <class 'retrying.RetryError'>

retrying.RetryError: RetryError[Attempts: 3, Value: None]
2020-05-29 16:02:23.141 | ERROR    | proxypool.processors.getter:run:36 - An error has been caught in function 'run', process 'Process-2' (19812), thread 'MainThread' (6168):
Traceback (most recent call last):
  File "<string>", line 1, in <module>
  File "D:\python37\lib\multiprocessing\spawn.py", line 105, in spawn_main
    exitcode = _main(fd)
               │     └ 3
               └ <function _main at 0x0000020678604EA0>
  File "D:\python37\lib\multiprocessing\spawn.py", line 118, in _main
    return self._bootstrap()
           │    └ <function BaseProcess._bootstrap at 0x00000206785C78C8>
           └ <Process(Process-2, started)>
  File "D:\python37\lib\multiprocessing\process.py", line 297, in _bootstrap
    self.run()
    │    └ <function BaseProcess.run at 0x00000206785B8F28>
    └ <Process(Process-2, started)>
  File "D:\python37\lib\multiprocessing\process.py", line 99, in run
    self._target(*self._args, **self._kwargs)
    │    │        │    │        │    └ {}
    │    │        │    │        └ <Process(Process-2, started)>
    │    │        │    └ ()
    │    │        └ <Process(Process-2, started)>
    │    └ <bound method Scheduler.run_getter of <proxypool.scheduler.Scheduler object at 0x0000020679F4BCC0>>
    └ <Process(Process-2, started)>

  File "E:\代理池\ProxyPool\proxypool\scheduler.py", line 48, in run_getter
    getter.run()
    │      └ <function Getter.run at 0x0000020679B13D08>
    └ <proxypool.processors.getter.Getter object at 0x00000206785C1E48>

> File "E:\代理池\ProxyPool\proxypool\processors\getter.py", line 36, in run
    for proxy in crawler.crawl():
        │        │       └ <function BaseCrawler.crawl at 0x0000020679B13510>
        │        └ <public.kuaidaili.KuaidailiCrawler object at 0x0000020679F4BC88>
        └ Proxy(host='175.155.139.172', port='1133')

  File "E:\代理池\ProxyPool\proxypool\crawlers\base.py", line 25, in crawl
    html = self.fetch(url)
    │      │    │     └ 'https://www.kuaidaili.com/free/inha/2/'
    │      │    └ <function BaseCrawler.fetch at 0x0000020679B13488>
    │      └ <public.kuaidaili.KuaidailiCrawler object at 0x0000020679F4BC88>
    └ '<!DOCTYPE html>\n<html>\n<head>\n<meta http-equiv="X-UA-Compatible" content="IE=edge" />\n<meta http-equiv="Content-Type" co...

  File "D:\python37\lib\site-packages\retrying.py", line 49, in wrapped_f
    return Retrying(*dargs, **dkw).call(f, *args, **kw)
           │         │        │         │   │       └ {}
           │         │        │         │   └ (<public.kuaidaili.KuaidailiCrawler object at 0x0000020679F4BC88>, 'https://www.kuaidaili.com/free/inha/2/')
           │         │        │         └ <function BaseCrawler.fetch at 0x0000020679B13400>
           │         │        └ {'stop_max_attempt_number': 3, 'retry_on_result': <function BaseCrawler.<lambda> at 0x00000206797547B8>}
           │         └ ()
           └ <class 'retrying.Retrying'>
  File "D:\python37\lib\site-packages\retrying.py", line 214, in call
    raise RetryError(attempt)
          │          └ Attempts: 3, Value: None
          └ <class 'retrying.RetryError'>

retrying.RetryError: RetryError[Attempts: 3, Value: None]
2020-05-29 16:04:09.458 | ERROR    | proxypool.processors.getter:run:36 - An error has been caught in function 'run', process 'Process-2' (19812), thread 'MainThread' (6168):
Traceback (most recent call last):
  File "<string>", line 1, in <module>
  File "D:\python37\lib\multiprocessing\spawn.py", line 105, in spawn_main
    exitcode = _main(fd)
               │     └ 3
               └ <function _main at 0x0000020678604EA0>
  File "D:\python37\lib\multiprocessing\spawn.py", line 118, in _main
    return self._bootstrap()
           │    └ <function BaseProcess._bootstrap at 0x00000206785C78C8>
           └ <Process(Process-2, started)>
  File "D:\python37\lib\multiprocessing\process.py", line 297, in _bootstrap
    self.run()
    │    └ <function BaseProcess.run at 0x00000206785B8F28>
    └ <Process(Process-2, started)>
  File "D:\python37\lib\multiprocessing\process.py", line 99, in run
    self._target(*self._args, **self._kwargs)
    │    │        │    │        │    └ {}
    │    │        │    │        └ <Process(Process-2, started)>
    │    │        │    └ ()
    │    │        └ <Process(Process-2, started)>
    │    └ <bound method Scheduler.run_getter of <proxypool.scheduler.Scheduler object at 0x0000020679F4BCC0>>
    └ <Process(Process-2, started)>

  File "E:\代理池\ProxyPool\proxypool\scheduler.py", line 48, in run_getter
    getter.run()
    │      └ <function Getter.run at 0x0000020679B13D08>
    └ <proxypool.processors.getter.Getter object at 0x00000206785C1E48>

> File "E:\代理池\ProxyPool\proxypool\processors\getter.py", line 36, in run
    for proxy in crawler.crawl():
        │        │       └ <function BaseCrawler.crawl at 0x0000020679B13510>
        │        └ <public.kuaidaili.KuaidailiCrawler object at 0x0000020679F4BC88>
        └ Proxy(host='175.155.139.172', port='1133')

  File "E:\代理池\ProxyPool\proxypool\crawlers\base.py", line 25, in crawl
    html = self.fetch(url)
    │      │    │     └ 'https://www.kuaidaili.com/free/inha/2/'
    │      │    └ <function BaseCrawler.fetch at 0x0000020679B13488>
    │      └ <public.kuaidaili.KuaidailiCrawler object at 0x0000020679F4BC88>
    └ '<!DOCTYPE html>\n<html>\n<head>\n<meta http-equiv="X-UA-Compatible" content="IE=edge" />\n<meta http-equiv="Content-Type" co...

  File "D:\python37\lib\site-packages\retrying.py", line 49, in wrapped_f
    return Retrying(*dargs, **dkw).call(f, *args, **kw)
           │         │        │         │   │       └ {}
           │         │        │         │   └ (<public.kuaidaili.KuaidailiCrawler object at 0x0000020679F4BC88>, 'https://www.kuaidaili.com/free/inha/2/')
           │         │        │         └ <function BaseCrawler.fetch at 0x0000020679B13400>
           │         │        └ {'stop_max_attempt_number': 3, 'retry_on_result': <function BaseCrawler.<lambda> at 0x00000206797547B8>}
           │         └ ()
           └ <class 'retrying.Retrying'>
  File "D:\python37\lib\site-packages\retrying.py", line 214, in call
    raise RetryError(attempt)
          │          └ Attempts: 3, Value: None
          └ <class 'retrying.RetryError'>

retrying.RetryError: RetryError[Attempts: 3, Value: None]
2020-05-29 16:05:55.832 | ERROR    | proxypool.processors.getter:run:36 - An error has been caught in function 'run', process 'Process-2' (19812), thread 'MainThread' (6168):
Traceback (most recent call last):
  File "<string>", line 1, in <module>
  File "D:\python37\lib\multiprocessing\spawn.py", line 105, in spawn_main
    exitcode = _main(fd)
               │     └ 3
               └ <function _main at 0x0000020678604EA0>
  File "D:\python37\lib\multiprocessing\spawn.py", line 118, in _main
    return self._bootstrap()
           │    └ <function BaseProcess._bootstrap at 0x00000206785C78C8>
           └ <Process(Process-2, started)>
  File "D:\python37\lib\multiprocessing\process.py", line 297, in _bootstrap
    self.run()
    │    └ <function BaseProcess.run at 0x00000206785B8F28>
    └ <Process(Process-2, started)>
  File "D:\python37\lib\multiprocessing\process.py", line 99, in run
    self._target(*self._args, **self._kwargs)
    │    │        │    │        │    └ {}
    │    │        │    │        └ <Process(Process-2, started)>
    │    │        │    └ ()
    │    │        └ <Process(Process-2, started)>
    │    └ <bound method Scheduler.run_getter of <proxypool.scheduler.Scheduler object at 0x0000020679F4BCC0>>
    └ <Process(Process-2, started)>

  File "E:\代理池\ProxyPool\proxypool\scheduler.py", line 48, in run_getter
    getter.run()
    │      └ <function Getter.run at 0x0000020679B13D08>
    └ <proxypool.processors.getter.Getter object at 0x00000206785C1E48>

> File "E:\代理池\ProxyPool\proxypool\processors\getter.py", line 36, in run
    for proxy in crawler.crawl():
        │        │       └ <function BaseCrawler.crawl at 0x0000020679B13510>
        │        └ <public.kuaidaili.KuaidailiCrawler object at 0x0000020679F4BC88>
        └ Proxy(host='175.155.139.172', port='1133')

  File "E:\代理池\ProxyPool\proxypool\crawlers\base.py", line 25, in crawl
    html = self.fetch(url)
    │      │    │     └ 'https://www.kuaidaili.com/free/inha/2/'
    │      │    └ <function BaseCrawler.fetch at 0x0000020679B13488>
    │      └ <public.kuaidaili.KuaidailiCrawler object at 0x0000020679F4BC88>
    └ '<!DOCTYPE html>\n<html>\n<head>\n<meta http-equiv="X-UA-Compatible" content="IE=edge" />\n<meta http-equiv="Content-Type" co...

  File "D:\python37\lib\site-packages\retrying.py", line 49, in wrapped_f
    return Retrying(*dargs, **dkw).call(f, *args, **kw)
           │         │        │         │   │       └ {}
           │         │        │         │   └ (<public.kuaidaili.KuaidailiCrawler object at 0x0000020679F4BC88>, 'https://www.kuaidaili.com/free/inha/2/')
           │         │        │         └ <function BaseCrawler.fetch at 0x0000020679B13400>
           │         │        └ {'stop_max_attempt_number': 3, 'retry_on_result': <function BaseCrawler.<lambda> at 0x00000206797547B8>}
           │         └ ()
           └ <class 'retrying.Retrying'>
  File "D:\python37\lib\site-packages\retrying.py", line 214, in call
    raise RetryError(attempt)
          │          └ Attempts: 3, Value: None
          └ <class 'retrying.RetryError'>

retrying.RetryError: RetryError[Attempts: 3, Value: None]
2020-05-29 16:07:43.274 | ERROR    | proxypool.processors.getter:run:36 - An error has been caught in function 'run', process 'Process-2' (19812), thread 'MainThread' (6168):
Traceback (most recent call last):
  File "<string>", line 1, in <module>
  File "D:\python37\lib\multiprocessing\spawn.py", line 105, in spawn_main
    exitcode = _main(fd)
               │     └ 3
               └ <function _main at 0x0000020678604EA0>
  File "D:\python37\lib\multiprocessing\spawn.py", line 118, in _main
    return self._bootstrap()
           │    └ <function BaseProcess._bootstrap at 0x00000206785C78C8>
           └ <Process(Process-2, started)>
  File "D:\python37\lib\multiprocessing\process.py", line 297, in _bootstrap
    self.run()
    │    └ <function BaseProcess.run at 0x00000206785B8F28>
    └ <Process(Process-2, started)>
  File "D:\python37\lib\multiprocessing\process.py", line 99, in run
    self._target(*self._args, **self._kwargs)
    │    │        │    │        │    └ {}
    │    │        │    │        └ <Process(Process-2, started)>
    │    │        │    └ ()
    │    │        └ <Process(Process-2, started)>
    │    └ <bound method Scheduler.run_getter of <proxypool.scheduler.Scheduler object at 0x0000020679F4BCC0>>
    └ <Process(Process-2, started)>

  File "E:\代理池\ProxyPool\proxypool\scheduler.py", line 48, in run_getter
    getter.run()
    │      └ <function Getter.run at 0x0000020679B13D08>
    └ <proxypool.processors.getter.Getter object at 0x00000206785C1E48>

> File "E:\代理池\ProxyPool\proxypool\processors\getter.py", line 36, in run
    for proxy in crawler.crawl():
        │        │       └ <function BaseCrawler.crawl at 0x0000020679B13510>
        │        └ <public.kuaidaili.KuaidailiCrawler object at 0x0000020679F4BC88>
        └ Proxy(host='175.155.139.172', port='1133')

  File "E:\代理池\ProxyPool\proxypool\crawlers\base.py", line 25, in crawl
    html = self.fetch(url)
    │      │    │     └ 'https://www.kuaidaili.com/free/inha/2/'
    │      │    └ <function BaseCrawler.fetch at 0x0000020679B13488>
    │      └ <public.kuaidaili.KuaidailiCrawler object at 0x0000020679F4BC88>
    └ '<!DOCTYPE html>\n<html>\n<head>\n<meta http-equiv="X-UA-Compatible" content="IE=edge" />\n<meta http-equiv="Content-Type" co...

  File "D:\python37\lib\site-packages\retrying.py", line 49, in wrapped_f
    return Retrying(*dargs, **dkw).call(f, *args, **kw)
           │         │        │         │   │       └ {}
           │         │        │         │   └ (<public.kuaidaili.KuaidailiCrawler object at 0x0000020679F4BC88>, 'https://www.kuaidaili.com/free/inha/2/')
           │         │        │         └ <function BaseCrawler.fetch at 0x0000020679B13400>
           │         │        └ {'stop_max_attempt_number': 3, 'retry_on_result': <function BaseCrawler.<lambda> at 0x00000206797547B8>}
           │         └ ()
           └ <class 'retrying.Retrying'>
  File "D:\python37\lib\site-packages\retrying.py", line 214, in call
    raise RetryError(attempt)
          │          └ Attempts: 3, Value: None
          └ <class 'retrying.RetryError'>

retrying.RetryError: RetryError[Attempts: 3, Value: None]
2020-05-29 16:38:58.952 | ERROR    | proxypool.scheduler:run_tester:33 - An error has been caught in function 'run_tester', process 'Process-1' (15176), thread 'MainThread' (25992):
Traceback (most recent call last):
  File "<string>", line 1, in <module>
  File "D:\python37\lib\multiprocessing\spawn.py", line 105, in spawn_main
    exitcode = _main(fd)
               │     └ 3
               └ <function _main at 0x000001E56E3F4EA0>
  File "D:\python37\lib\multiprocessing\spawn.py", line 118, in _main
    return self._bootstrap()
           │    └ <function BaseProcess._bootstrap at 0x000001E56E3B78C8>
           └ <Process(Process-1, started)>
  File "D:\python37\lib\multiprocessing\process.py", line 297, in _bootstrap
    self.run()
    │    └ <function BaseProcess.run at 0x000001E56E3A8F28>
    └ <Process(Process-1, started)>
  File "D:\python37\lib\multiprocessing\process.py", line 99, in run
    self._target(*self._args, **self._kwargs)
    │    │        │    │        │    └ {}
    │    │        │    │        └ <Process(Process-1, started)>
    │    │        │    └ ()
    │    │        └ <Process(Process-1, started)>
    │    └ <bound method Scheduler.run_tester of <proxypool.scheduler.Scheduler object at 0x000001E56FD3BD68>>
    └ <Process(Process-1, started)>

> File "E:\代理池\ProxyPool\proxypool\scheduler.py", line 33, in run_tester
    tester.run()
    │      └ <function Tester.run at 0x000001E56FD53400>
    └ <proxypool.processors.tester.Tester object at 0x000001E56E3B1D68>

  File "E:\代理池\ProxyPool\proxypool\processors\tester.py", line 69, in run
    tasks = [self.test(proxy) for proxy in proxies]
    │        │    │                        └ None
    │        │    └ <function Tester.test at 0x000001E56FD3AF28>
    │        └ <proxypool.processors.tester.Tester object at 0x000001E56E3B1D68>
    └ [<coroutine object Tester.test at 0x000001E56FD83248>, <coroutine object Tester.test at 0x000001E56FD83C48>, <coroutine objec...

TypeError: 'NoneType' object is not iterable
2020-05-29 16:45:42.975 | ERROR    | proxypool.scheduler:run_tester:33 - An error has been caught in function 'run_tester', process 'Process-1' (15176), thread 'MainThread' (25992):
Traceback (most recent call last):
  File "<string>", line 1, in <module>
  File "D:\python37\lib\multiprocessing\spawn.py", line 105, in spawn_main
    exitcode = _main(fd)
               │     └ 3
               └ <function _main at 0x000001E56E3F4EA0>
  File "D:\python37\lib\multiprocessing\spawn.py", line 118, in _main
    return self._bootstrap()
           │    └ <function BaseProcess._bootstrap at 0x000001E56E3B78C8>
           └ <Process(Process-1, started)>
  File "D:\python37\lib\multiprocessing\process.py", line 297, in _bootstrap
    self.run()
    │    └ <function BaseProcess.run at 0x000001E56E3A8F28>
    └ <Process(Process-1, started)>
  File "D:\python37\lib\multiprocessing\process.py", line 99, in run
    self._target(*self._args, **self._kwargs)
    │    │        │    │        │    └ {}
    │    │        │    │        └ <Process(Process-1, started)>
    │    │        │    └ ()
    │    │        └ <Process(Process-1, started)>
    │    └ <bound method Scheduler.run_tester of <proxypool.scheduler.Scheduler object at 0x000001E56FD3BD68>>
    └ <Process(Process-1, started)>

> File "E:\代理池\ProxyPool\proxypool\scheduler.py", line 33, in run_tester
    tester.run()
    │      └ <function Tester.run at 0x000001E56FD53400>
    └ <proxypool.processors.tester.Tester object at 0x000001E56E3B1D68>

  File "E:\代理池\ProxyPool\proxypool\processors\tester.py", line 69, in run
    tasks = [self.test(proxy) for proxy in proxies]
    │        │    │                        └ None
    │        │    └ <function Tester.test at 0x000001E56FD3AF28>
    │        └ <proxypool.processors.tester.Tester object at 0x000001E56E3B1D68>
    └ [<coroutine object Tester.test at 0x000001E56FD7C848>, <coroutine object Tester.test at 0x000001E56FD7C4C8>, <coroutine objec...

TypeError: 'NoneType' object is not iterable
2020-05-29 16:52:16.945 | ERROR    | proxypool.scheduler:run_tester:33 - An error has been caught in function 'run_tester', process 'Process-1' (15176), thread 'MainThread' (25992):
Traceback (most recent call last):
  File "<string>", line 1, in <module>
  File "D:\python37\lib\multiprocessing\spawn.py", line 105, in spawn_main
    exitcode = _main(fd)
               │     └ 3
               └ <function _main at 0x000001E56E3F4EA0>
  File "D:\python37\lib\multiprocessing\spawn.py", line 118, in _main
    return self._bootstrap()
           │    └ <function BaseProcess._bootstrap at 0x000001E56E3B78C8>
           └ <Process(Process-1, started)>
  File "D:\python37\lib\multiprocessing\process.py", line 297, in _bootstrap
    self.run()
    │    └ <function BaseProcess.run at 0x000001E56E3A8F28>
    └ <Process(Process-1, started)>
  File "D:\python37\lib\multiprocessing\process.py", line 99, in run
    self._target(*self._args, **self._kwargs)
    │    │        │    │        │    └ {}
    │    │        │    │        └ <Process(Process-1, started)>
    │    │        │    └ ()
    │    │        └ <Process(Process-1, started)>
    │    └ <bound method Scheduler.run_tester of <proxypool.scheduler.Scheduler object at 0x000001E56FD3BD68>>
    └ <Process(Process-1, started)>

> File "E:\代理池\ProxyPool\proxypool\scheduler.py", line 33, in run_tester
    tester.run()
    │      └ <function Tester.run at 0x000001E56FD53400>
    └ <proxypool.processors.tester.Tester object at 0x000001E56E3B1D68>

  File "E:\代理池\ProxyPool\proxypool\processors\tester.py", line 69, in run
    tasks = [self.test(proxy) for proxy in proxies]
    │        │    │                        └ None
    │        │    └ <function Tester.test at 0x000001E56FD3AF28>
    │        └ <proxypool.processors.tester.Tester object at 0x000001E56E3B1D68>
    └ [<coroutine object Tester.test at 0x000001E56FD6A5C8>, <coroutine object Tester.test at 0x000001E56FD6AF48>, <coroutine objec...

TypeError: 'NoneType' object is not iterable
2020-05-29 16:58:28.945 | ERROR    | proxypool.scheduler:run_tester:33 - An error has been caught in function 'run_tester', process 'Process-1' (15176), thread 'MainThread' (25992):
Traceback (most recent call last):
  File "<string>", line 1, in <module>
  File "D:\python37\lib\multiprocessing\spawn.py", line 105, in spawn_main
    exitcode = _main(fd)
               │     └ 3
               └ <function _main at 0x000001E56E3F4EA0>
  File "D:\python37\lib\multiprocessing\spawn.py", line 118, in _main
    return self._bootstrap()
           │    └ <function BaseProcess._bootstrap at 0x000001E56E3B78C8>
           └ <Process(Process-1, started)>
  File "D:\python37\lib\multiprocessing\process.py", line 297, in _bootstrap
    self.run()
    │    └ <function BaseProcess.run at 0x000001E56E3A8F28>
    └ <Process(Process-1, started)>
  File "D:\python37\lib\multiprocessing\process.py", line 99, in run
    self._target(*self._args, **self._kwargs)
    │    │        │    │        │    └ {}
    │    │        │    │        └ <Process(Process-1, started)>
    │    │        │    └ ()
    │    │        └ <Process(Process-1, started)>
    │    └ <bound method Scheduler.run_tester of <proxypool.scheduler.Scheduler object at 0x000001E56FD3BD68>>
    └ <Process(Process-1, started)>

> File "E:\代理池\ProxyPool\proxypool\scheduler.py", line 33, in run_tester
    tester.run()
    │      └ <function Tester.run at 0x000001E56FD53400>
    └ <proxypool.processors.tester.Tester object at 0x000001E56E3B1D68>

  File "E:\代理池\ProxyPool\proxypool\processors\tester.py", line 69, in run
    tasks = [self.test(proxy) for proxy in proxies]
    │        │    │                        └ None
    │        │    └ <function Tester.test at 0x000001E56FD3AF28>
    │        └ <proxypool.processors.tester.Tester object at 0x000001E56E3B1D68>
    └ [<coroutine object Tester.test at 0x000001E56FDA2548>, <coroutine object Tester.test at 0x000001E56FDA2048>, <coroutine objec...

TypeError: 'NoneType' object is not iterable
2020-05-29 17:04:18.953 | ERROR    | proxypool.scheduler:run_tester:33 - An error has been caught in function 'run_tester', process 'Process-1' (15176), thread 'MainThread' (25992):
Traceback (most recent call last):
  File "<string>", line 1, in <module>
  File "D:\python37\lib\multiprocessing\spawn.py", line 105, in spawn_main
    exitcode = _main(fd)
               │     └ 3
               └ <function _main at 0x000001E56E3F4EA0>
  File "D:\python37\lib\multiprocessing\spawn.py", line 118, in _main
    return self._bootstrap()
           │    └ <function BaseProcess._bootstrap at 0x000001E56E3B78C8>
           └ <Process(Process-1, started)>
  File "D:\python37\lib\multiprocessing\process.py", line 297, in _bootstrap
    self.run()
    │    └ <function BaseProcess.run at 0x000001E56E3A8F28>
    └ <Process(Process-1, started)>
  File "D:\python37\lib\multiprocessing\process.py", line 99, in run
    self._target(*self._args, **self._kwargs)
    │    │        │    │        │    └ {}
    │    │        │    │        └ <Process(Process-1, started)>
    │    │        │    └ ()
    │    │        └ <Process(Process-1, started)>
    │    └ <bound method Scheduler.run_tester of <proxypool.scheduler.Scheduler object at 0x000001E56FD3BD68>>
    └ <Process(Process-1, started)>

> File "E:\代理池\ProxyPool\proxypool\scheduler.py", line 33, in run_tester
    tester.run()
    │      └ <function Tester.run at 0x000001E56FD53400>
    └ <proxypool.processors.tester.Tester object at 0x000001E56E3B1D68>

  File "E:\代理池\ProxyPool\proxypool\processors\tester.py", line 69, in run
    tasks = [self.test(proxy) for proxy in proxies]
    │        │    │                        └ None
    │        │    └ <function Tester.test at 0x000001E56FD3AF28>
    │        └ <proxypool.processors.tester.Tester object at 0x000001E56E3B1D68>
    └ [<coroutine object Tester.test at 0x000001E56FDA29C8>, <coroutine object Tester.test at 0x000001E56FDA2DC8>, <coroutine objec...

TypeError: 'NoneType' object is not iterable
2020-05-29 17:09:46.957 | ERROR    | proxypool.scheduler:run_tester:33 - An error has been caught in function 'run_tester', process 'Process-1' (15176), thread 'MainThread' (25992):
Traceback (most recent call last):
  File "<string>", line 1, in <module>
  File "D:\python37\lib\multiprocessing\spawn.py", line 105, in spawn_main
    exitcode = _main(fd)
               │     └ 3
               └ <function _main at 0x000001E56E3F4EA0>
  File "D:\python37\lib\multiprocessing\spawn.py", line 118, in _main
    return self._bootstrap()
           │    └ <function BaseProcess._bootstrap at 0x000001E56E3B78C8>
           └ <Process(Process-1, started)>
  File "D:\python37\lib\multiprocessing\process.py", line 297, in _bootstrap
    self.run()
    │    └ <function BaseProcess.run at 0x000001E56E3A8F28>
    └ <Process(Process-1, started)>
  File "D:\python37\lib\multiprocessing\process.py", line 99, in run
    self._target(*self._args, **self._kwargs)
    │    │        │    │        │    └ {}
    │    │        │    │        └ <Process(Process-1, started)>
    │    │        │    └ ()
    │    │        └ <Process(Process-1, started)>
    │    └ <bound method Scheduler.run_tester of <proxypool.scheduler.Scheduler object at 0x000001E56FD3BD68>>
    └ <Process(Process-1, started)>

> File "E:\代理池\ProxyPool\proxypool\scheduler.py", line 33, in run_tester
    tester.run()
    │      └ <function Tester.run at 0x000001E56FD53400>
    └ <proxypool.processors.tester.Tester object at 0x000001E56E3B1D68>

  File "E:\代理池\ProxyPool\proxypool\processors\tester.py", line 69, in run
    tasks = [self.test(proxy) for proxy in proxies]
    │        │    │                        └ None
    │        │    └ <function Tester.test at 0x000001E56FD3AF28>
    │        └ <proxypool.processors.tester.Tester object at 0x000001E56E3B1D68>
    └ [<coroutine object Tester.test at 0x000001E56FE86048>, <coroutine object Tester.test at 0x000001E56FE86C48>, <coroutine objec...

TypeError: 'NoneType' object is not iterable
2020-05-29 17:14:52.988 | ERROR    | proxypool.scheduler:run_tester:33 - An error has been caught in function 'run_tester', process 'Process-1' (15176), thread 'MainThread' (25992):
Traceback (most recent call last):
  File "<string>", line 1, in <module>
  File "D:\python37\lib\multiprocessing\spawn.py", line 105, in spawn_main
    exitcode = _main(fd)
               │     └ 3
               └ <function _main at 0x000001E56E3F4EA0>
  File "D:\python37\lib\multiprocessing\spawn.py", line 118, in _main
    return self._bootstrap()
           │    └ <function BaseProcess._bootstrap at 0x000001E56E3B78C8>
           └ <Process(Process-1, started)>
  File "D:\python37\lib\multiprocessing\process.py", line 297, in _bootstrap
    self.run()
    │    └ <function BaseProcess.run at 0x000001E56E3A8F28>
    └ <Process(Process-1, started)>
  File "D:\python37\lib\multiprocessing\process.py", line 99, in run
    self._target(*self._args, **self._kwargs)
    │    │        │    │        │    └ {}
    │    │        │    │        └ <Process(Process-1, started)>
    │    │        │    └ ()
    │    │        └ <Process(Process-1, started)>
    │    └ <bound method Scheduler.run_tester of <proxypool.scheduler.Scheduler object at 0x000001E56FD3BD68>>
    └ <Process(Process-1, started)>

> File "E:\代理池\ProxyPool\proxypool\scheduler.py", line 33, in run_tester
    tester.run()
    │      └ <function Tester.run at 0x000001E56FD53400>
    └ <proxypool.processors.tester.Tester object at 0x000001E56E3B1D68>

  File "E:\代理池\ProxyPool\proxypool\processors\tester.py", line 69, in run
    tasks = [self.test(proxy) for proxy in proxies]
    │        │    │                        └ None
    │        │    └ <function Tester.test at 0x000001E56FD3AF28>
    │        └ <proxypool.processors.tester.Tester object at 0x000001E56E3B1D68>
    └ [<coroutine object Tester.test at 0x000001E56FD9BDC8>, <coroutine object Tester.test at 0x000001E56FD9BA48>, <coroutine objec...

TypeError: 'NoneType' object is not iterable
2020-05-29 17:19:36.945 | ERROR    | proxypool.scheduler:run_tester:33 - An error has been caught in function 'run_tester', process 'Process-1' (15176), thread 'MainThread' (25992):
Traceback (most recent call last):
  File "<string>", line 1, in <module>
  File "D:\python37\lib\multiprocessing\spawn.py", line 105, in spawn_main
    exitcode = _main(fd)
               │     └ 3
               └ <function _main at 0x000001E56E3F4EA0>
  File "D:\python37\lib\multiprocessing\spawn.py", line 118, in _main
    return self._bootstrap()
           │    └ <function BaseProcess._bootstrap at 0x000001E56E3B78C8>
           └ <Process(Process-1, started)>
  File "D:\python37\lib\multiprocessing\process.py", line 297, in _bootstrap
    self.run()
    │    └ <function BaseProcess.run at 0x000001E56E3A8F28>
    └ <Process(Process-1, started)>
  File "D:\python37\lib\multiprocessing\process.py", line 99, in run
    self._target(*self._args, **self._kwargs)
    │    │        │    │        │    └ {}
    │    │        │    │        └ <Process(Process-1, started)>
    │    │        │    └ ()
    │    │        └ <Process(Process-1, started)>
    │    └ <bound method Scheduler.run_tester of <proxypool.scheduler.Scheduler object at 0x000001E56FD3BD68>>
    └ <Process(Process-1, started)>

> File "E:\代理池\ProxyPool\proxypool\scheduler.py", line 33, in run_tester
    tester.run()
    │      └ <function Tester.run at 0x000001E56FD53400>
    └ <proxypool.processors.tester.Tester object at 0x000001E56E3B1D68>

  File "E:\代理池\ProxyPool\proxypool\processors\tester.py", line 69, in run
    tasks = [self.test(proxy) for proxy in proxies]
    │        │    │                        └ None
    │        │    └ <function Tester.test at 0x000001E56FD3AF28>
    │        └ <proxypool.processors.tester.Tester object at 0x000001E56E3B1D68>
    └ [<coroutine object Tester.test at 0x000001E56FDE42C8>, <coroutine object Tester.test at 0x000001E56FDE40C8>, <coroutine objec...

TypeError: 'NoneType' object is not iterable
2020-05-29 17:23:58.972 | ERROR    | proxypool.scheduler:run_tester:33 - An error has been caught in function 'run_tester', process 'Process-1' (15176), thread 'MainThread' (25992):
Traceback (most recent call last):
  File "<string>", line 1, in <module>
  File "D:\python37\lib\multiprocessing\spawn.py", line 105, in spawn_main
    exitcode = _main(fd)
               │     └ 3
               └ <function _main at 0x000001E56E3F4EA0>
  File "D:\python37\lib\multiprocessing\spawn.py", line 118, in _main
    return self._bootstrap()
           │    └ <function BaseProcess._bootstrap at 0x000001E56E3B78C8>
           └ <Process(Process-1, started)>
  File "D:\python37\lib\multiprocessing\process.py", line 297, in _bootstrap
    self.run()
    │    └ <function BaseProcess.run at 0x000001E56E3A8F28>
    └ <Process(Process-1, started)>
  File "D:\python37\lib\multiprocessing\process.py", line 99, in run
    self._target(*self._args, **self._kwargs)
    │    │        │    │        │    └ {}
    │    │        │    │        └ <Process(Process-1, started)>
    │    │        │    └ ()
    │    │        └ <Process(Process-1, started)>
    │    └ <bound method Scheduler.run_tester of <proxypool.scheduler.Scheduler object at 0x000001E56FD3BD68>>
    └ <Process(Process-1, started)>

> File "E:\代理池\ProxyPool\proxypool\scheduler.py", line 33, in run_tester
    tester.run()
    │      └ <function Tester.run at 0x000001E56FD53400>
    └ <proxypool.processors.tester.Tester object at 0x000001E56E3B1D68>

  File "E:\代理池\ProxyPool\proxypool\processors\tester.py", line 69, in run
    tasks = [self.test(proxy) for proxy in proxies]
    │        │    │                        └ None
    │        │    └ <function Tester.test at 0x000001E56FD3AF28>
    │        └ <proxypool.processors.tester.Tester object at 0x000001E56E3B1D68>
    └ [<coroutine object Tester.test at 0x000001E56FD29DC8>, <coroutine object Tester.test at 0x000001E56FD29EC8>, <coroutine objec...

TypeError: 'NoneType' object is not iterable
2020-05-29 17:28:09.955 | ERROR    | proxypool.scheduler:run_tester:33 - An error has been caught in function 'run_tester', process 'Process-1' (15176), thread 'MainThread' (25992):
Traceback (most recent call last):
  File "<string>", line 1, in <module>
  File "D:\python37\lib\multiprocessing\spawn.py", line 105, in spawn_main
    exitcode = _main(fd)
               │     └ 3
               └ <function _main at 0x000001E56E3F4EA0>
  File "D:\python37\lib\multiprocessing\spawn.py", line 118, in _main
    return self._bootstrap()
           │    └ <function BaseProcess._bootstrap at 0x000001E56E3B78C8>
           └ <Process(Process-1, started)>
  File "D:\python37\lib\multiprocessing\process.py", line 297, in _bootstrap
    self.run()
    │    └ <function BaseProcess.run at 0x000001E56E3A8F28>
    └ <Process(Process-1, started)>
  File "D:\python37\lib\multiprocessing\process.py", line 99, in run
    self._target(*self._args, **self._kwargs)
    │    │        │    │        │    └ {}
    │    │        │    │        └ <Process(Process-1, started)>
    │    │        │    └ ()
    │    │        └ <Process(Process-1, started)>
    │    └ <bound method Scheduler.run_tester of <proxypool.scheduler.Scheduler object at 0x000001E56FD3BD68>>
    └ <Process(Process-1, started)>

> File "E:\代理池\ProxyPool\proxypool\scheduler.py", line 33, in run_tester
    tester.run()
    │      └ <function Tester.run at 0x000001E56FD53400>
    └ <proxypool.processors.tester.Tester object at 0x000001E56E3B1D68>

  File "E:\代理池\ProxyPool\proxypool\processors\tester.py", line 69, in run
    tasks = [self.test(proxy) for proxy in proxies]
    │        │    │                        └ None
    │        │    └ <function Tester.test at 0x000001E56FD3AF28>
    │        └ <proxypool.processors.tester.Tester object at 0x000001E56E3B1D68>
    └ [<coroutine object Tester.test at 0x000001E56FDB3E48>, <coroutine object Tester.test at 0x000001E56FDB36C8>, <coroutine objec...

TypeError: 'NoneType' object is not iterable
2020-05-29 17:32:09.950 | ERROR    | proxypool.scheduler:run_tester:33 - An error has been caught in function 'run_tester', process 'Process-1' (15176), thread 'MainThread' (25992):
Traceback (most recent call last):
  File "<string>", line 1, in <module>
  File "D:\python37\lib\multiprocessing\spawn.py", line 105, in spawn_main
    exitcode = _main(fd)
               │     └ 3
               └ <function _main at 0x000001E56E3F4EA0>
  File "D:\python37\lib\multiprocessing\spawn.py", line 118, in _main
    return self._bootstrap()
           │    └ <function BaseProcess._bootstrap at 0x000001E56E3B78C8>
           └ <Process(Process-1, started)>
  File "D:\python37\lib\multiprocessing\process.py", line 297, in _bootstrap
    self.run()
    │    └ <function BaseProcess.run at 0x000001E56E3A8F28>
    └ <Process(Process-1, started)>
  File "D:\python37\lib\multiprocessing\process.py", line 99, in run
    self._target(*self._args, **self._kwargs)
    │    │        │    │        │    └ {}
    │    │        │    │        └ <Process(Process-1, started)>
    │    │        │    └ ()
    │    │        └ <Process(Process-1, started)>
    │    └ <bound method Scheduler.run_tester of <proxypool.scheduler.Scheduler object at 0x000001E56FD3BD68>>
    └ <Process(Process-1, started)>

> File "E:\代理池\ProxyPool\proxypool\scheduler.py", line 33, in run_tester
    tester.run()
    │      └ <function Tester.run at 0x000001E56FD53400>
    └ <proxypool.processors.tester.Tester object at 0x000001E56E3B1D68>

  File "E:\代理池\ProxyPool\proxypool\processors\tester.py", line 69, in run
    tasks = [self.test(proxy) for proxy in proxies]
    │        │    │                        └ None
    │        │    └ <function Tester.test at 0x000001E56FD3AF28>
    │        └ <proxypool.processors.tester.Tester object at 0x000001E56E3B1D68>
    └ [<coroutine object Tester.test at 0x000001E56FD0E648>, <coroutine object Tester.test at 0x000001E56FD0E6C8>, <coroutine objec...

TypeError: 'NoneType' object is not iterable
2020-05-29 17:35:58.945 | ERROR    | proxypool.scheduler:run_tester:33 - An error has been caught in function 'run_tester', process 'Process-1' (15176), thread 'MainThread' (25992):
Traceback (most recent call last):
  File "<string>", line 1, in <module>
  File "D:\python37\lib\multiprocessing\spawn.py", line 105, in spawn_main
    exitcode = _main(fd)
               │     └ 3
               └ <function _main at 0x000001E56E3F4EA0>
  File "D:\python37\lib\multiprocessing\spawn.py", line 118, in _main
    return self._bootstrap()
           │    └ <function BaseProcess._bootstrap at 0x000001E56E3B78C8>
           └ <Process(Process-1, started)>
  File "D:\python37\lib\multiprocessing\process.py", line 297, in _bootstrap
    self.run()
    │    └ <function BaseProcess.run at 0x000001E56E3A8F28>
    └ <Process(Process-1, started)>
  File "D:\python37\lib\multiprocessing\process.py", line 99, in run
    self._target(*self._args, **self._kwargs)
    │    │        │    │        │    └ {}
    │    │        │    │        └ <Process(Process-1, started)>
    │    │        │    └ ()
    │    │        └ <Process(Process-1, started)>
    │    └ <bound method Scheduler.run_tester of <proxypool.scheduler.Scheduler object at 0x000001E56FD3BD68>>
    └ <Process(Process-1, started)>

> File "E:\代理池\ProxyPool\proxypool\scheduler.py", line 33, in run_tester
    tester.run()
    │      └ <function Tester.run at 0x000001E56FD53400>
    └ <proxypool.processors.tester.Tester object at 0x000001E56E3B1D68>

  File "E:\代理池\ProxyPool\proxypool\processors\tester.py", line 69, in run
    tasks = [self.test(proxy) for proxy in proxies]
    │        │    │                        └ None
    │        │    └ <function Tester.test at 0x000001E56FD3AF28>
    │        └ <proxypool.processors.tester.Tester object at 0x000001E56E3B1D68>
    └ [<coroutine object Tester.test at 0x000001E56FD6AF48>, <coroutine object Tester.test at 0x000001E56FD6A1C8>, <coroutine objec...

TypeError: 'NoneType' object is not iterable
2020-05-29 17:39:36.952 | ERROR    | proxypool.scheduler:run_tester:33 - An error has been caught in function 'run_tester', process 'Process-1' (15176), thread 'MainThread' (25992):
Traceback (most recent call last):
  File "<string>", line 1, in <module>
  File "D:\python37\lib\multiprocessing\spawn.py", line 105, in spawn_main
    exitcode = _main(fd)
               │     └ 3
               └ <function _main at 0x000001E56E3F4EA0>
  File "D:\python37\lib\multiprocessing\spawn.py", line 118, in _main
    return self._bootstrap()
           │    └ <function BaseProcess._bootstrap at 0x000001E56E3B78C8>
           └ <Process(Process-1, started)>
  File "D:\python37\lib\multiprocessing\process.py", line 297, in _bootstrap
    self.run()
    │    └ <function BaseProcess.run at 0x000001E56E3A8F28>
    └ <Process(Process-1, started)>
  File "D:\python37\lib\multiprocessing\process.py", line 99, in run
    self._target(*self._args, **self._kwargs)
    │    │        │    │        │    └ {}
    │    │        │    │        └ <Process(Process-1, started)>
    │    │        │    └ ()
    │    │        └ <Process(Process-1, started)>
    │    └ <bound method Scheduler.run_tester of <proxypool.scheduler.Scheduler object at 0x000001E56FD3BD68>>
    └ <Process(Process-1, started)>

> File "E:\代理池\ProxyPool\proxypool\scheduler.py", line 33, in run_tester
    tester.run()
    │      └ <function Tester.run at 0x000001E56FD53400>
    └ <proxypool.processors.tester.Tester object at 0x000001E56E3B1D68>

  File "E:\代理池\ProxyPool\proxypool\processors\tester.py", line 69, in run
    tasks = [self.test(proxy) for proxy in proxies]
    │        │    │                        └ None
    │        │    └ <function Tester.test at 0x000001E56FD3AF28>
    │        └ <proxypool.processors.tester.Tester object at 0x000001E56E3B1D68>
    └ [<coroutine object Tester.test at 0x000001E56FD8A2C8>, <coroutine object Tester.test at 0x000001E56FD8AC48>, <coroutine objec...

TypeError: 'NoneType' object is not iterable
2020-05-29 17:43:03.972 | ERROR    | proxypool.scheduler:run_tester:33 - An error has been caught in function 'run_tester', process 'Process-1' (15176), thread 'MainThread' (25992):
Traceback (most recent call last):
  File "<string>", line 1, in <module>
  File "D:\python37\lib\multiprocessing\spawn.py", line 105, in spawn_main
    exitcode = _main(fd)
               │     └ 3
               └ <function _main at 0x000001E56E3F4EA0>
  File "D:\python37\lib\multiprocessing\spawn.py", line 118, in _main
    return self._bootstrap()
           │    └ <function BaseProcess._bootstrap at 0x000001E56E3B78C8>
           └ <Process(Process-1, started)>
  File "D:\python37\lib\multiprocessing\process.py", line 297, in _bootstrap
    self.run()
    │    └ <function BaseProcess.run at 0x000001E56E3A8F28>
    └ <Process(Process-1, started)>
  File "D:\python37\lib\multiprocessing\process.py", line 99, in run
    self._target(*self._args, **self._kwargs)
    │    │        │    │        │    └ {}
    │    │        │    │        └ <Process(Process-1, started)>
    │    │        │    └ ()
    │    │        └ <Process(Process-1, started)>
    │    └ <bound method Scheduler.run_tester of <proxypool.scheduler.Scheduler object at 0x000001E56FD3BD68>>
    └ <Process(Process-1, started)>

> File "E:\代理池\ProxyPool\proxypool\scheduler.py", line 33, in run_tester
    tester.run()
    │      └ <function Tester.run at 0x000001E56FD53400>
    └ <proxypool.processors.tester.Tester object at 0x000001E56E3B1D68>

  File "E:\代理池\ProxyPool\proxypool\processors\tester.py", line 69, in run
    tasks = [self.test(proxy) for proxy in proxies]
    │        │    │                        └ None
    │        │    └ <function Tester.test at 0x000001E56FD3AF28>
    │        └ <proxypool.processors.tester.Tester object at 0x000001E56E3B1D68>
    └ [<coroutine object Tester.test at 0x000001E56FD8F948>, <coroutine object Tester.test at 0x000001E56FD8FBC8>, <coroutine objec...

TypeError: 'NoneType' object is not iterable
